Workbook

Sheet Czytaj_mnie
A1: HCV w Polsce – model inwestycji w testowanie i leczenie (arkusz z formułami)
A2: Wszystkie wyniki są SZACUNKAMI MODELU, nie danymi. Stan danych: 28.10.2026 (wersja po audycie 2). Arkusze L_* i Inw_*: S0 (zaniechanie), I1, I2, I3, I4, I5, V1 wobec status quo (S1). ICER główny = perspektywa NFZ.
A3: Przełącznik Ustawienia!B5 (x_testy): 0 = wariant pełny (testy w porównaniu); 1 = testy finansuje inny płatnik – porównujemy tylko koszt wyleczenia (leki, monitorowanie, nawigacja) z kosztami nieleczenia. To przesunięcie kosztu testów do innego płatnika, nie jego zniknięcie z finansów publicznych.
A4: Arkusz Na_pacjenta: koszt wyleczenia vs koszt nieleczenia na jednego zdiagnozowanego pacjenta. Arkusz Analizy_scen: warianty założeń (K=1, cena 2017, malejąca zapadalność, opieka u wszystkich itd.). Arkusz Zmiany: lista zmian 28.10.2026.
A5: Żółte komórki = dane wejściowe (nazwy x_…). Zmiana parametru kosztowego przelicza koszty, salda, ROI i rok zwrotu.
A6: Liczebności stanów (arkusze L_*) pochodzą z silnika Markowa (JavaScript, ten sam co w aplikacji) i są wklejone jako wartości;
A7: zmiana parametrów przejść/epidemiologii wymaga ponownego uruchomienia silnika (kalkulator w aplikacji robi to na żywo).
A8: Perspektywy (AOTMiT): NFZ; sektor publiczny = NFZ + budżet (MZ/SW) + ZUS + KRUS + utracone składki i PIT; społeczna = NFZ + budżet + produktywność (ZUS to transfery).
A9: Dyskonto: koszty 5%, efekty 3,5% (AOTMiT). Saldo > 0 = koszt netto dla państwa; saldo < 0 = oszczędność netto.
A10: Liczby leczonych są roczne – nie sumuj osób między latami (suma kursów leczenia ≠ liczba unikalnych osób).
A11: Materiał edukacyjny, neutralny; bez nazw leków i firm. Recenzja panelu ról w aplikacji jest symulowana.
A12: Deklaracja finansowania i konfliktu interesów: Autor pracuje w sektorze farmaceutycznym. Analiza powstała prywatnie, bez zlecenia i finansowania jakiejkolwiek firmy. Nie wymienia ani nie promuje żadnych produktów leczniczych. Część wykorzystanych źródeł była finansowana przez przemysł — oznaczono to w Źródłach.

Sheet Parametry
A1: id | B1: nazwa | C1: wartosc | D1: min | E1: max | F1: rozklad | G1: param_rozkladu | H1: zrodlo | I1: data_zrodla | J1: typ | K1: metoda | L1: platnik | M1: jednostka
A2: N0 | B2: Osoby z wiremią HCV w PL na start (2026) | C2: 155000 | D2: 145000 | E2: 165000 | F2: trójkątny | G2: min=145000; moda=155000; max=165000 | H2: Szacunki ekspertów i Polaris Observatory (przegląd w raporcie HCV); Flisiak i in. Eur J Gastroenterol Hepatol 2015;27:70–76 | I2: 2020–2024 | J2: dane źródłowe | K2: punkt środkowy przedziału publikowanych szacunków | L2: — | M2: osoby
A3: AGE0 | B3: Wiek startowy kohorty | C3: 53.33 | D3: 47.33 | E3: 59.33 | F3: normalny | G3: sd=3 | H3: NFZ app-stat B.71 2025 wg grup wieku (n=4 839) | I3: 2025 | J3: prognoza/szacunek | K3: średnia ważona środków grup wieku B.71 2025 (18–40 z 7–17: 29; 41–60: 50,5; 61–80: 70,5; 81+: 85 – założenie); przesuwa cały rozkład wieku kohorty; SD 3 lata w PSA = założenie (niepewność, czy leczeni odzwierciedlają niewykrytych) | L3: — | M3: lata
A4: RET | B4: Wiek emerytalny ważony płcią | C4: 63 | D4: 60 | E4: 65 | F4: stały (tornado) | G4: — | H4: NFZ B.71 2025 wg płci (M 55,5%); ustawa o emeryturach (60/65) | I4: 2025 | J4: prognoza/szacunek | K4: średnia ważona udziałem płci | L4: — | M4: lata
A5: D_F0 | B5: Rozkład włóknienia na starcie F0 | C5: 0.213 | F5: Dirichlet | G5: alfa=180 (n=845) | H5: Pierucka 2016 (nowo rozpoznani, n=845) | I5: 2016 | J5: dane źródłowe | K5: udział obserwowany | L5: — | M5: odsetek
A6: D_F1 | B6: Rozkład włóknienia na starcie F1 | C6: 0.361 | F6: Dirichlet | G6: alfa=305 (n=845) | H6: Pierucka 2016 (nowo rozpoznani, n=845) | I6: 2016 | J6: dane źródłowe | K6: udział obserwowany | L6: — | M6: odsetek
A7: D_F2 | B7: Rozkład włóknienia na starcie F2 | C7: 0.233 | F7: Dirichlet | G7: alfa=197 (n=845) | H7: Pierucka 2016 (nowo rozpoznani, n=845) | I7: 2016 | J7: dane źródłowe | K7: udział obserwowany | L7: — | M7: odsetek
A8: D_F3 | B8: Rozkład włóknienia na starcie F3 | C8: 0.11 | F8: Dirichlet | G8: alfa=93 (n=845) | H8: Pierucka 2016 (nowo rozpoznani, n=845) | I8: 2016 | J8: dane źródłowe | K8: udział obserwowany | L8: — | M8: odsetek
A9: D_F4 | B9: Rozkład włóknienia na starcie F4 | C9: 0.083 | F9: Dirichlet | G9: alfa=70 (n=845) | H9: Pierucka 2016 (nowo rozpoznani, n=845) | I9: 2016 | J9: dane źródłowe | K9: udział obserwowany | L9: — | M9: odsetek
A10: p_F0F1 | B10: Prawdopodobieństwo roczne F0→F1 | C10: 0.117 | D10: 0.104 | E10: 0.13 | F10: beta | G10: alfa=274.65; beta=2072.75 | H10: Thein 2008 Hepatology 48:418 (metaanaliza), doi 10.1002/hep.22375 | I10: 2008 | J10: dane zagraniczne/literatura międzynarodowa | K10: metaanaliza; SE=(górny−dolny 95% CI)/3,92 | L10: — | M10: /rok
A11: p_F1F2 | B11: Prawdopodobieństwo roczne F1→F2 | C11: 0.085 | D11: 0.075 | E11: 0.096 | F11: beta | G11: alfa=230.27; beta=2478.76 | H11: Thein 2008 Hepatology 48:418 (metaanaliza), doi 10.1002/hep.22375 | I11: 2008 | J11: dane zagraniczne/literatura międzynarodowa | K11: metaanaliza; SE=(górny−dolny 95% CI)/3,92 | L11: — | M11: /rok
A12: p_F2F3 | B12: Prawdopodobieństwo roczne F2→F3 | C12: 0.12 | D12: 0.109 | E12: 0.133 | F12: beta | G12: alfa=337.94; beta=2478.23 | H12: Thein 2008 Hepatology 48:418 (metaanaliza), doi 10.1002/hep.22375 | I12: 2008 | J12: dane zagraniczne/literatura międzynarodowa | K12: metaanaliza; SE=(górny−dolny 95% CI)/3,92 | L12: — | M12: /rok
A13: p_F3F4 | B13: Prawdopodobieństwo roczne F3→F4 | C13: 0.116 | D13: 0.104 | E13: 0.129 | F13: beta | G13: alfa=292.34; beta=2227.83 | H13: Thein 2008 Hepatology 48:418 (metaanaliza), doi 10.1002/hep.22375 | I13: 2008 | J13: dane zagraniczne/literatura międzynarodowa | K13: metaanaliza; SE=(górny−dolny 95% CI)/3,92 | L13: — | M13: /rok
A14: p_CCDC | B14: Prawdopodobieństwo roczne CC→DC | C14: 0.0592 | D14: 0.0272 | E14: 0.08 | F14: beta | G14: alfa=186.85; beta=2969.48 | H14: Analiza ekonomiczna wnioskodawcy przygotowana przez firmę konsultingową, opublikowana w BIP AOTMiT (zlecenie 153/2017): wartości Tab. 28, błędy standardowe do PSA Tab. 198 – parametry z literatury międzynarodowej (źródło przygotowane na zlecenie wnioskodawcy – możliwa stronniczość sponsora) | I14: 2017 | J14: dane źródłowe (PL HTA; pierwotnie lit. międzynar.) | K14: — | L14: — | M14: /rok
A15: p_CCHCC | B15: Prawdopodobieństwo roczne CC→HCC | C15: 0.0367 | D15: 0.02 | E15: 0.048 | F15: beta | G15: alfa=112.20; beta=2945.03 | H15: Analiza ekonomiczna wnioskodawcy przygotowana przez firmę konsultingową, opublikowana w BIP AOTMiT (zlecenie 153/2017): wartości Tab. 28, błędy standardowe do PSA Tab. 198 – parametry z literatury międzynarodowej (źródło przygotowane na zlecenie wnioskodawcy – możliwa stronniczość sponsora) | I15: 2017 | J15: dane źródłowe (PL HTA; pierwotnie lit. międzynar.) | K15: — | L15: — | M15: /rok
A16: p_DCHCC | B16: Prawdopodobieństwo roczne DC→HCC | C16: 0.0215 | D16: 0.0131 | E16: 0.0681 | F16: beta | G16: alfa=28.25; beta=1285.61 | H16: Analiza ekonomiczna wnioskodawcy przygotowana przez firmę konsultingową, opublikowana w BIP AOTMiT (zlecenie 153/2017): wartości Tab. 28, błędy standardowe do PSA Tab. 198 – parametry z literatury międzynarodowej (źródło przygotowane na zlecenie wnioskodawcy – możliwa stronniczość sponsora) | I16: 2017 | J16: dane źródłowe (PL HTA; pierwotnie lit. międzynar.) | K16: — | L16: — | M16: /rok
A17: p_DCLT | B17: Prawdopodobieństwo roczne DC→LT | C17: 0.0418 | D17: 0.0376 | E17: 0.046 | F17: beta | G17: alfa=3.02; beta=69.13 | H17: Analiza ekonomiczna wnioskodawcy przygotowana przez firmę konsultingową, opublikowana w BIP AOTMiT (zlecenie 153/2017): wartości Tab. 28, błędy standardowe do PSA Tab. 198 – parametry z literatury międzynarodowej (źródło przygotowane na zlecenie wnioskodawcy – możliwa stronniczość sponsora) | I17: 2017 | J17: dane źródłowe (PL HTA; pierwotnie lit. międzynar.) | K17: — | L17: — | M17: /rok
A18: p_DCD | B18: Prawdopodobieństwo roczne DC→zgon wątrobowy | C18: 0.1081 | D18: 0.0934 | E18: 0.1228 | F18: beta | G18: alfa=185.18; beta=1527.85 | H18: Analiza ekonomiczna wnioskodawcy przygotowana przez firmę konsultingową, opublikowana w BIP AOTMiT (zlecenie 153/2017): wartości Tab. 28, błędy standardowe do PSA Tab. 198 – parametry z literatury międzynarodowej (źródło przygotowane na zlecenie wnioskodawcy – możliwa stronniczość sponsora) | I18: 2017 | J18: dane źródłowe (PL HTA; pierwotnie lit. międzynar.) | K18: — | L18: — | M18: /rok
A19: p_HCCD | B19: Prawdopodobieństwo roczne HCC→zgon wątrobowy | C19: 0.2715 | D19: 0.257 | E19: 0.286 | F19: beta | G19: alfa=980.36; beta=2630.54 | H19: Analiza ekonomiczna wnioskodawcy przygotowana przez firmę konsultingową, opublikowana w BIP AOTMiT (zlecenie 153/2017): wartości Tab. 28, błędy standardowe do PSA Tab. 198 – parametry z literatury międzynarodowej (źródło przygotowane na zlecenie wnioskodawcy – możliwa stronniczość sponsora) | I19: 2017 | J19: dane źródłowe (PL HTA; pierwotnie lit. międzynar.) | K19: — | L19: — | M19: /rok
A20: p_HCCLT | B20: Prawdopodobieństwo roczne HCC→LT | C20: 0.0093 | D20: 0.0084 | E20: 0.0103 | F20: beta | G20: alfa=342.73; beta=36510.31 | H20: Analiza ekonomiczna wnioskodawcy przygotowana przez firmę konsultingową, opublikowana w BIP AOTMiT (zlecenie 153/2017): wartości Tab. 28, błędy standardowe do PSA Tab. 198 – parametry z literatury międzynarodowej (źródło przygotowane na zlecenie wnioskodawcy – możliwa stronniczość sponsora) | I20: 2017 | J20: dane źródłowe (PL HTA; pierwotnie lit. międzynar.) | K20: — | L20: — | M20: /rok
A21: p_LTD | B21: Prawdopodobieństwo roczne LT (rok 1)→zgon | C21: 0.18 | D21: 0.175 | E21: 0.185 | F21: beta | G21: alfa=4250.70; beta=19364.30 | H21: Analiza ekonomiczna wnioskodawcy przygotowana przez firmę konsultingową, opublikowana w BIP AOTMiT (zlecenie 153/2017): wartości Tab. 28, błędy standardowe do PSA Tab. 198 – parametry z literatury międzynarodowej (źródło przygotowane na zlecenie wnioskodawcy – możliwa stronniczość sponsora) | I21: 2017 | J21: dane źródłowe (PL HTA; pierwotnie lit. międzynar.) | K21: — | L21: — | M21: /rok
... A32: u_SVR | B32: Przyrost użyteczności po SVR | C32: 0.055 | D32: 0.044 | E32: 0.066 | F32: gamma | G32: k=100.00; theta=0.0005 | H32: Analiza ekonomiczna wnioskodawcy przygotowana przez firmę konsultingową, opublikowana w BIP AOTMiT (zlecenie 153/2017): wartości Tab. 28, błędy standardowe do PSA Tab. 198 – parametry z literatury międzynarodowej (źródło przygotowane na zlecenie wnioskodawcy – możliwa stronniczość sponsora) | I32: 2017 | J32: dane źródłowe | K32: — | L32: — | M32: QALY/rok
A33: CPI | B33: Indeks CPI GUS 2016→2025 | C33: 1.5758813 | F33: stały | G33: — | H33: GUS: wskaźniki cen towarów i usług konsumpcyjnych 1950–2025 (rok poprzedni=100) | I33: 2026 | J33: prognoza/szacunek | K33: inflacja kosztu: iloczyn rocznych CPI 2017–2025 (102,0;101,6;102,3;103,4;105,1;114,4;111,4;103,6;103,6) | L33: — | M33: indeks
A34: c_F | B34: Koszt NFZ/rok: F0–F3 bez leczenia (ceny 2025) | C34: 2960.2457 | D34: 2368.2 | E34: 3552.29 | F34: gamma | G34: k=61.47; theta=48.1607 | H34: Kaczor 2012 (koszty stanów, ceny 2016) via analiza ekonomiczna wnioskodawcy (firma konsultingowa) opublikowana w BIP AOTMiT, zlecenie 153/2017, Tab. 73/198 × CPI GUS | I34: 2016→2025 | J34: prognoza/szacunek | K34: wartość źródłowa 1878.47 zł (2016) × CPI 1.5759; SE źródłowe przeskalowane | L34: NFZ | M34: zł/os./rok
A35: c_SVRn | B35: Koszt NFZ/rok: F0–F3 po SVR (ceny 2025) | C35: 612.59233 | D35: 490.07 | E35: 735.11 | F35: gamma | G35: k=61.47; theta=9.9653 | H35: Kaczor 2012 (koszty stanów, ceny 2016) via analiza ekonomiczna wnioskodawcy (firma konsultingowa) opublikowana w BIP AOTMiT, zlecenie 153/2017, Tab. 73/198 × CPI GUS | I35: 2016→2025 | J35: prognoza/szacunek | K35: wartość źródłowa 388.73 zł (2016) × CPI 1.5759; SE źródłowe przeskalowane | L35: NFZ | M35: zł/os./rok
A36: c_CC | B36: Koszt NFZ/rok: CC (ceny 2025) | C36: 5415.4687 | D36: 4332.37 | E36: 6498.56 | F36: gamma | G36: k=100.00; theta=54.1556 | H36: Kaczor 2012 (koszty stanów, ceny 2016) via analiza ekonomiczna wnioskodawcy (firma konsultingowa) opublikowana w BIP AOTMiT, zlecenie 153/2017, Tab. 73/198 × CPI GUS | I36: 2016→2025 | J36: prognoza/szacunek | K36: wartość źródłowa 3436.47 zł (2016) × CPI 1.5759; SE źródłowe przeskalowane | L36: NFZ | M36: zł/os./rok
A37: c_SVRcc | B37: Koszt NFZ/rok: CC po SVR (ceny 2025) | C37: 2738.0622 | D37: 2190.45 | E37: 3285.67 | F37: gamma | G37: k=100.00; theta=27.3813 | H37: Kaczor 2012 (koszty stanów, ceny 2016) via analiza ekonomiczna wnioskodawcy (firma konsultingowa) opublikowana w BIP AOTMiT, zlecenie 153/2017, Tab. 73/198 × CPI GUS | I37: 2016→2025 | J37: prognoza/szacunek | K37: wartość źródłowa 1737.48 zł (2016) × CPI 1.5759; SE źródłowe przeskalowane | L37: NFZ | M37: zł/os./rok
A38: c_DC | B38: Koszt NFZ/rok: DC (ceny 2025) | C38: 18064.831 | D38: 14451.87 | E38: 21677.8 | F38: gamma | G38: k=100.00; theta=180.6477 | H38: Kaczor 2012 (koszty stanów, ceny 2016) via analiza ekonomiczna wnioskodawcy (firma konsultingowa) opublikowana w BIP AOTMiT, zlecenie 153/2017, Tab. 73/198 × CPI GUS | I38: 2016→2025 | J38: prognoza/szacunek | K38: wartość źródłowa 11463.32 zł (2016) × CPI 1.5759; SE źródłowe przeskalowane | L38: NFZ | M38: zł/os./rok
A39: c_HCC | B39: Koszt NFZ/rok: HCC (ceny 2025) | C39: 62879.885 | D39: 50303.91 | E39: 75455.86 | F39: gamma | G39: k=100.00; theta=628.7985 | H39: Kaczor 2012 (koszty stanów, ceny 2016) via analiza ekonomiczna wnioskodawcy (firma konsultingowa) opublikowana w BIP AOTMiT, zlecenie 153/2017, Tab. 73/198 × CPI GUS | I39: 2016→2025 | J39: prognoza/szacunek | K39: wartość źródłowa 39901.41 zł (2016) × CPI 1.5759; SE źródłowe przeskalowane | L39: NFZ | M39: zł/os./rok
A40: c_LT | B40: Koszt NFZ/rok: LT (rok przeszczepienia) (ceny 2025) | C40: 342818.35 | D40: 274254.68 | E40: 411382.02 | F40: gamma | G40: k=100.00; theta=3428.1828 | H40: Kaczor 2012 (koszty stanów, ceny 2016) via analiza ekonomiczna wnioskodawcy (firma konsultingowa) opublikowana w BIP AOTMiT, zlecenie 153/2017, Tab. 73/198 × CPI GUS | I40: 2016→2025 | J40: prognoza/szacunek | K40: wartość źródłowa 217540.72 zł (2016) × CPI 1.5759; SE źródłowe przeskalowane | L40: NFZ | M40: zł/os./rok
A41: c_PLT | B41: Koszt NFZ/rok: po LT (rok 2+) (ceny 2025) | C41: 31787.81 | D41: 25430.25 | E41: 38145.37 | F41: gamma | G41: k=100.00; theta=317.8797 | H41: Kaczor 2012 (koszty stanów, ceny 2016) via analiza ekonomiczna wnioskodawcy (firma konsultingowa) opublikowana w BIP AOTMiT, zlecenie 153/2017, Tab. 73/198 × CPI GUS | I41: 2016→2025 | J41: prognoza/szacunek | K41: wartość źródłowa 20171.45 zł (2016) × CPI 1.5759; SE źródłowe przeskalowane | L41: NFZ | M41: zł/os./rok
A42: c_DAA | B42: Koszt DAA na pacjenta (refundacja B.71) | C42: 22760 | D42: 17366 | E42: 29829 | F42: lognormalny | G42: mu=ln(22760); sigma=0.138 (SD logarytmu ilorazu 2017–2025, n=9) | H42: NFZ app-stat B.71: 109,98 mln zł / 4 832 pacjentów (2025); szereg 2017–2025 (33 872 zł w 2017 → 22 760 zł w 2025) | I42: 2017–2025 | J42: dane źródłowe | K42: iloraz wartość/pacjenci; zmienność = SD logarytmu ilorazu 2017–2025; min/max = 95% rozkładu (17,4–29,8 tys. zł); scenariusze: 33 872 zł (2017) i najwyższa cena urzędowa terapii 8 tyg. w wykazie MZ 2025 (97 716 zł) – tylko w analizie scenariuszowej | L42: NFZ | M42: zł/pacjent
A43: c_MON | B43: Ryczałt diagnostyczny/monitorowanie B.71 (ceny 2025) | C43: 5765.1299 | D43: 3731.52 | E43: 6918.16 | F43: gamma | G43: SE 10% | H43: Zarządzenie 53/2017/DGL (5.08.08.0000002) 3 731,52 zł × CPI 2017→2025 | I43: 2017→2025 | J43: prognoza/szacunek | K43: inflacja kosztu CPI GUS 2018–2025 | L43: NFZ | M43: zł/pacjent
A44: c_AHCV | B44: Badanie anty-HCV (POZ) | C44: 46.2 | D44: 40 | E44: 57 | F44: stały | G44: — | H44: Zarządzenie Prezesa NFZ 22/2025/DSOZ (tekst ujedn. 23.09.2026) via psoz.pl | I44: 2026 | J44: dane źródłowe | K44: — | L44: NFZ | M44: zł/test
A45: c_RNA | B45: Badanie HCV RNA jakościowe | C45: 180 | D45: 150 | E45: 235 | F45: stały | G45: — | H45: Cennik laboratorium komercyjnego od 01.02.2025 (brak taryfy NFZ dla POZ – proxy rynkowe) | I45: 2025 | J45: dane źródłowe (proxy) | K45: cena rynkowa jako proxy | L45: NFZ | M45: zł/test
... A47: VIR | B47: Odsetek wiremicznych wśród anty-HCV+ | C47: 0.4 | D47: 0.35 | E47: 0.5 | F47: beta | G47: alfa=40; beta=60 | H47: Flisiak i in. (Clin Exp Hepatol 2020) | I47: 2020 | J47: dane źródłowe | K47: — | L47: — | M47: odsetek
A48: PREV_K | B48: Odsetek anty-HCV+ wśród PWID | C48: 0.312 | F48: stały | G48: — | H48: KCPU 2021 (31,2%); Rosińska i in. BMC Infect Dis 2015 (59%, dane 2004–05), doi 10.1186/s12879-015-0828-9 | I48: 2021/2004–05 | J48: dane źródłowe | K48: informacyjnie – wydajność kanału liczona z Y_KEY | L48: MZ/SW | M48: odsetek
A49: VIR_K | B49: Odsetek wiremicznych wśród anty-HCV+ PWID | C49: 0.5 | D49: 0.4 | E49: 0.7 | F49: beta | G49: alfa=50; beta=50 | H49: KBPN 'Serwis Informacyjny Uzależnienia' 79 (≥ połowa wiremiczna) | I49: 2017 | J49: dane źródłowe | K49: dolna granica 'co najmniej połowa' | L49: MZ/SW | M49: odsetek
A50: T_SQ | B50: Leczeni/rok – status quo | C50: 4832 | D50: 4407 | E50: 5200 | F50: stały | G50: — | H50: NFZ app-stat B.71 2025 | I50: 2025 | J50: dane źródłowe | K50: ostatnia obserwacja; wariant: trend liniowy 2020–2025 (n=6; +138/rok; R²=0,57) i log-liniowy (R²=0,55) | L50: NFZ | M50: osoby/rok
A51: T_WHO | B51: Leczeni/rok – eliminacja WHO 2030 | C51: 17500 | D51: 15000 | E51: 20000 | F51: stały | G51: — | H51: Flisiak i in. 2015 (scenariusz eliminacji: 15 000/rok); eksperci 2026 (ok. 20 000/rok) | I51: 2023 | J51: dane źródłowe | K51: środek przedziału | L51: NFZ | M51: osoby/rok
...

Sheet Ustawienia
A1: nazwa | B1: wartość | C1: opis
A2: x_dk | B2: 0.05 | C2: stopa dyskontowa kosztów (AOTMiT 5%)
A3: x_de | B3: 0.035 | C3: stopa dyskontowa efektów (AOTMiT 3,5%)
A4: x_H | B4: 20 | C4: horyzont analizy w latach (1–50)
A5: x_testy | B5: 0 | C5: 1 = testy i koszty stałe programu finansuje inny płatnik (wyłączone z porównania); 0 = wariant pełny

Sheet L_S1
A1: S1: Status quo (4 832 leczonych/rok) – liczebności (silnik, wartości) i koszty (formuły), zł/rok, niezdyskontowane. Szacunek modelu.
A2: rok | B2: t | C2: treated | D2: NFZ_diag | E2: MZ_SW | F2: nNAV | G2: FIXon | H2: cF03 | I2: cF4 | J2: cDC | K2: cHCC | L2: cPLT | M2: cSVn | N2: cSVc | O2: cLTn | P2: cLT1 | Q2: wAdv | R2: wHCC | S2: wGH | T2: cAbs | U2: cAbsW | V2: QALY | W2: newDC | X2: newHCC | Y2: LT | Z2: liverD | AA2: NFZ_med | AB2: NFZ_DAA | AC2: NFZ_mon | AD2: NFZ_diag_k | AE2: MZ_SW_k | AF2: NAV_k | AG2: FIX_k | AH2: ZUS | AI2: KRUS | AJ2: lostw | AK2: lost_FUS | AL2: lost_NFZ | AM2: lost_PIT | AN2: lost_FP | AO2: NFZ | AP2: PUBLIC | AQ2: SOCIETAL | AR2: INV_NFZ | AS2: INV_PUB
A3: 2026 | B3: 0 | C3: 4832 | D3: 0 | E3: 0 | F3: 0 | G3: 0 | H3: 2320.855 | I3: 208.058 | J3: 1579.412 | K3: 2524.99 | L3: 1540.438 | M3: 6431.679 | N3: 567.81 | O3: 89.046 | P3: 44.523 | Q3: 2134.761 | R3: 1703.413 | S3: 312.377 | T3: 2528.914 | U3: 1400.363 | V3: 113392.92 | W3: 265.86 | X3: 711.886 | Y3: 89.046 | Z3: 922.327 | AA3: =H3*x_c_F+I3*x_c_CC+J3*x_c_DC+K3*x_c_HCC+L3*x_c_PLT+M3*x_c_SVRn+N3*x_c_SVRcc+O3*x_c_LT+P3*x_c_LT1 -> 2.8240502e+08 | AB3: =C3*x_c_DAA -> 109976320 | AC3: =C3*x_c_MON -> 27857108 | AD3: =D3*(1-x_testy) -> 0 | AE3: =E3*(1-x_testy) -> 0 | AF3: =F3*x_NAV -> 0 | AG3: =G3*x_FIX*(1-x_testy) -> 0 | AH3: =x_z_F*U3+(1-x_AGRI)*x_EMP*x_WLOSS*(x_PEN_K74*Q3+x_PEN_C22*R3) -> 27364032 | AI3: =x_AGRI*x_EMP*x_WLOSS*(x_PEN_K74*Q3+x_PEN_C22*R3) -> 1618412.6 | AJ3: =x_EMP*x_WAGE*(x_WLOSS*(Q3+R3)+S3)+U3*x_ABS_D*x_WAGE/365 -> 1.5637604e+08 | AK3: =AJ3*x_R_FUS -> 49477379 | AL3: =AJ3*x_R_NFZ -> 12144320 | AM3: =AJ3*x_R_PIT -> 10396532 | AN3: =AJ3*x_R_FP -> 3987589 | AO3: =AA3+AB3+AC3+AD3+AF3 -> 4.2023845e+08 | AP3: =AO3+AE3+AG3+AH3+AI3+AK3+AL3+AM3+AN3 -> 5.2522671e+08 | AQ3: =AO3+AE3+AG3+AJ3 -> 5.7661449e+08 | AR3: =AB3+AC3+AD3+AF3 -> 1.3783343e+08 | AS3: =AR3+AE3+AG3 -> 1.3783343e+08
A4: 2027 | B4: 1 | C4: 4832 | D4: 0 | E4: 0 | F4: 0 | G4: 0 | H4: 2307.655 | I4: 219.602 | J4: 1564.594 | K4: 2522.589 | L4: 1489.389 | M4: 10633.791 | N4: 958.016 | O4: 87.923 | P4: 88.484 | Q4: 2138.396 | R4: 1717.819 | S4: 940.006 | T4: 2527.257 | U4: 1441.565 | V4: 114502.79 | W4: 275.683 | X4: 742.641 | Y4: 87.923 | Z4: 925.838 | AA4: =H4*x_c_F+I4*x_c_CC+J4*x_c_DC+K4*x_c_HCC+L4*x_c_PLT+M4*x_c_SVRn+N4*x_c_SVRcc+O4*x_c_LT+P4*x_c_LT1 -> 2.857346e+08 | AB4: =C4*x_c_DAA -> 109976320 | AC4: =C4*x_c_MON -> 27857108 | AD4: =D4*(1-x_testy) -> 0 | AE4: =E4*(1-x_testy) -> 0 | AF4: =F4*x_NAV -> 0 | AG4: =G4*x_FIX*(1-x_testy) -> 0 | AH4: =x_z_F*U4+(1-x_AGRI)*x_EMP*x_WLOSS*(x_PEN_K74*Q4+x_PEN_C22*R4) -> 27569082 | AI4: =x_AGRI*x_EMP*x_WLOSS*(x_PEN_K74*Q4+x_PEN_C22*R4) -> 1626367 | AJ4: =x_EMP*x_WAGE*(x_WLOSS*(Q4+R4)+S4)+U4*x_ABS_D*x_WAGE/365 -> 2.1059953e+08 | AK4: =AJ4*x_R_FUS -> 66633692 | AL4: =AJ4*x_R_NFZ -> 16355370 | AM4: =AJ4*x_R_PIT -> 14001536 | AN4: =AJ4*x_R_FP -> 5370288 | AO4: =AA4+AB4+AC4+AD4+AF4 -> 4.2356803e+08 | AP4: =AO4+AE4+AG4+AH4+AI4+AK4+AL4+AM4+AN4 -> 5.5512437e+08 | AQ4: =AO4+AE4+AG4+AJ4 -> 6.3416756e+08 | AR4: =AB4+AC4+AD4+AF4 -> 1.3783343e+08 | AS4: =AR4+AE4+AG4 -> 1.3783343e+08
A5: 2028 | B5: 2 | C5: 4832 | D5: 0 | E5: 0 | F5: 0 | G5: 0 | H5: 2293.265 | I5: 232.353 | J5: 1562.24 | K5: 2550.931 | L5: 1475.77 | M5: 14757.577 | N5: 1359.883 | O5: 87.651 | P5: 87.787 | Q5: 2147.743 | R5: 1757.091 | S5: 1573.278 | T5: 2525.618 | U5: 1481.15 | V5: 115688.46 | W5: 287.283 | X5: 774.535 | Y5: 87.651 | Z5: 927.579 | AA5: =H5*x_c_F+I5*x_c_CC+J5*x_c_DC+K5*x_c_HCC+L5*x_c_PLT+M5*x_c_SVRn+N5*x_c_SVRcc+O5*x_c_LT+P5*x_c_LT1 -> 2.9056791e+08 | AB5: =C5*x_c_DAA -> 109976320 | AC5: =C5*x_c_MON -> 27857108 | AD5: =D5*(1-x_testy) -> 0 | AE5: =E5*(1-x_testy) -> 0 | AF5: =F5*x_NAV -> 0 | AG5: =G5*x_FIX*(1-x_testy) -> 0 | AH5: =x_z_F*U5+(1-x_AGRI)*x_EMP*x_WLOSS*(x_PEN_K74*Q5+x_PEN_C22*R5) -> 27975146 | AI5: =x_AGRI*x_EMP*x_WLOSS*(x_PEN_K74*Q5+x_PEN_C22*R5) -> 1647827.8 | AJ5: =x_EMP*x_WAGE*(x_WLOSS*(Q5+R5)+S5)+U5*x_ABS_D*x_WAGE/365 -> 2.6630026e+08 | AK5: =AJ5*x_R_FUS -> 84257403 | AL5: =AJ5*x_R_NFZ -> 20681145 | AM5: =AJ5*x_R_PIT -> 17704753 | AN5: =AJ5*x_R_FP -> 6790656.7 | AO5: =AA5+AB5+AC5+AD5+AF5 -> 4.2840134e+08 | AP5: =AO5+AE5+AG5+AH5+AI5+AK5+AL5+AM5+AN5 -> 5.8745827e+08 | AQ5: =AO5+AE5+AG5+AJ5 -> 6.947016e+08 | AR5: =AB5+AC5+AD5+AF5 -> 1.3783343e+08 | AS5: =AR5+AE5+AG5 -> 1.3783343e+08
A6: 2029 | B6: 3 | C6: 4832 | D6: 0 | E6: 0 | F6: 0 | G6: 0 | H6: 2278.401 | I6: 245.586 | J6: 1571.333 | K6: 2601.368 | L6: 1461.227 | M6: 18799.94 | N6: 1773.467 | O6: 88.124 | P6: 87.888 | Q6: 2166.882 | R6: 1814.876 | S6: 2215.331 | T6: 2523.987 | U6: 1519.149 | V6: 116926.82 | W6: 299.555 | X6: 805.722 | Y6: 88.124 | Z6: 937.757 | AA6: =H6*x_c_F+I6*x_c_CC+J6*x_c_DC+K6*x_c_HCC+L6*x_c_PLT+M6*x_c_SVRn+N6*x_c_SVRcc+O6*x_c_LT+P6*x_c_LT1 -> 2.9724471e+08 | AB6: =C6*x_c_DAA -> 109976320 | AC6: =C6*x_c_MON -> 27857108 | AD6: =D6*(1-x_testy) -> 0 | AE6: =E6*(1-x_testy) -> 0 | AF6: =F6*x_NAV -> 0 | AG6: =G6*x_FIX*(1-x_testy) -> 0 | AH6: =x_z_F*U6+(1-x_AGRI)*x_EMP*x_WLOSS*(x_PEN_K74*Q6+x_PEN_C22*R6) -> 28563403 | AI6: =x_AGRI*x_EMP*x_WLOSS*(x_PEN_K74*Q6+x_PEN_C22*R6) -> 1681546.7 | AJ6: =x_EMP*x_WAGE*(x_WLOSS*(Q6+R6)+S6)+U6*x_ABS_D*x_WAGE/365 -> 3.2367147e+08 | AK6: =AJ6*x_R_FUS -> 1.0240965e+08 | AL6: =AJ6*x_R_NFZ -> 25136650 | AM6: =AJ6*x_R_PIT -> 21519030 | AN6: =AJ6*x_R_FP -> 8253622.5 | AO6: =AA6+AB6+AC6+AD6+AF6 -> 4.3507814e+08 | AP6: =AO6+AE6+AG6+AH6+AI6+AK6+AL6+AM6+AN6 -> 6.2264205e+08 | AQ6: =AO6+AE6+AG6+AJ6 -> 7.5874961e+08 | AR6: =AB6+AC6+AD6+AF6 -> 1.3783343e+08 | AS6: =AR6+AE6+AG6 -> 1.3783343e+08
A7: 2030 | B7: 4 | C7: 4832 | D7: 0 | E7: 0 | F7: 0 | G7: 0 | H7: 2263.649 | I7: 258.71 | J7: 1590.035 | K7: 2666.072 | L7: 1446.439 | M7: 22759 | N7: 2197.668 | O7: 89.202 | P7: 88.663 | Q7: 2194.943 | R7: 1885.483 | S7: 2871.709 | T7: 2522.359 | U7: 1555.596 | V7: 118203.52 | W7: 311.65 | X7: 834.807 | Y7: 89.202 | Z7: 953.972 | AA7: =H7*x_c_F+I7*x_c_CC+J7*x_c_DC+K7*x_c_HCC+L7*x_c_PLT+M7*x_c_SVRn+N7*x_c_SVRcc+O7*x_c_LT+P7*x_c_LT1 -> 3.0520165e+08 | AB7: =C7*x_c_DAA -> 109976320 | AC7: =C7*x_c_MON -> 27857108 | AD7: =D7*(1-x_testy) -> 0 | AE7: =E7*(1-x_testy) -> 0 | AF7: =F7*x_NAV -> 0 | AG7: =G7*x_FIX*(1-x_testy) -> 0 | AH7: =x_z_F*U7+(1-x_AGRI)*x_EMP*x_WLOSS*(x_PEN_K74*Q7+x_PEN_C22*R7) -> 29289784 | AI7: =x_AGRI*x_EMP*x_WLOSS*(x_PEN_K74*Q7+x_PEN_C22*R7) -> 1724606.3 | AJ7: =x_EMP*x_WAGE*(x_WLOSS*(Q7+R7)+S7)+U7*x_ABS_D*x_WAGE/365 -> 3.8297119e+08 | AK7: =AJ7*x_R_FUS -> 1.2117209e+08 | AL7: =AJ7*x_R_NFZ -> 29741926 | AM7: =AJ7*x_R_PIT -> 25461523 | AN7: =AJ7*x_R_FP -> 9765765.4 | AO7: =AA7+AB7+AC7+AD7+AF7 -> 4.4303508e+08 | AP7: =AO7+AE7+AG7+AH7+AI7+AK7+AL7+AM7+AN7 -> 6.6019077e+08 | AQ7: =AO7+AE7+AG7+AJ7 -> 8.2600627e+08 | AR7: =AB7+AC7+AD7+AF7 -> 1.3783343e+08 | AS7: =AR7+AE7+AG7 -> 1.3783343e+08
A8: 2031 | B8: 5 | C8: 4832 | D8: 0 | E8: 0 | F8: 0 | G8: 0 | H8: 2249.476 | I8: 271.252 | J8: 1616.09 | K8: 2738.254 | L8: 1431.964 | M8: 26634.076 | N8: 2630.502 | O8: 90.728 | P8: 89.965 | Q8: 2230.668 | R8: 1963.977 | S8: 3546.222 | T8: 2520.729 | U8: 1590.528 | V8: 119508.27 | W8: 322.934 | X8: 860.79 | Y8: 90.728 | Z8: 974.025 | AA8: =H8*x_c_F+I8*x_c_CC+J8*x_c_DC+K8*x_c_HCC+L8*x_c_PLT+M8*x_c_SVRn+N8*x_c_SVRcc+O8*x_c_LT+P8*x_c_LT1 -> 3.1392097e+08 | AB8: =C8*x_c_DAA -> 109976320 | AC8: =C8*x_c_MON -> 27857108 | AD8: =D8*(1-x_testy) -> 0 | AE8: =E8*(1-x_testy) -> 0 | AF8: =F8*x_NAV -> 0 | AG8: =G8*x_FIX*(1-x_testy) -> 0 | AH8: =x_z_F*U8+(1-x_AGRI)*x_EMP*x_WLOSS*(x_PEN_K74*Q8+x_PEN_C22*R8) -> 30113064 | AI8: =x_AGRI*x_EMP*x_WLOSS*(x_PEN_K74*Q8+x_PEN_C22*R8) -> 1774276.6 | AJ8: =x_EMP*x_WAGE*(x_WLOSS*(Q8+R8)+S8)+U8*x_ABS_D*x_WAGE/365 -> 4.4432167e+08 | AK8: =AJ8*x_R_FUS -> 1.4058338e+08 | AL8: =AJ8*x_R_NFZ -> 34506465 | AM8: =AJ8*x_R_PIT -> 29540359 | AN8: =AJ8*x_R_FP -> 11330203 | AO8: =AA8+AB8+AC8+AD8+AF8 -> 4.5175439e+08 | AP8: =AO8+AE8+AG8+AH8+AI8+AK8+AL8+AM8+AN8 -> 6.9960214e+08 | AQ8: =AO8+AE8+AG8+AJ8 -> 8.9607607e+08 | AR8: =AB8+AC8+AD8+AF8 -> 1.3783343e+08 | AS8: =AR8+AE8+AG8 -> 1.3783343e+08
A9: 2032 | B9: 6 | C9: 4832 | D9: 0 | E9: 0 | F9: 0 | G9: 0 | H9: 2236.247 | I9: 282.847 | J9: 1647.059 | K9: 2812.173 | L9: 1418.185 | M9: 30425.008 | N9: 3069.267 | O9: 92.542 | P9: 91.635 | Q9: 2272.551 | R9: 2046.171 | S9: 4241.049 | T9: 2519.094 | U9: 1623.998 | V9: 120830.92 | W9: 332.945 | X9: 882.962 | Y9: 92.542 | Z9: 995.927 | AA9: =H9*x_c_F+I9*x_c_CC+J9*x_c_DC+K9*x_c_HCC+L9*x_c_PLT+M9*x_c_SVRn+N9*x_c_SVRcc+O9*x_c_LT+P9*x_c_LT1 -> 3.2293899e+08 | AB9: =C9*x_c_DAA -> 109976320 | AC9: =C9*x_c_MON -> 27857108 | AD9: =D9*(1-x_testy) -> 0 | AE9: =E9*(1-x_testy) -> 0 | AF9: =F9*x_NAV -> 0 | AG9: =G9*x_FIX*(1-x_testy) -> 0 | AH9: =x_z_F*U9+(1-x_AGRI)*x_EMP*x_WLOSS*(x_PEN_K74*Q9+x_PEN_C22*R9) -> 30995673 | AI9: =x_AGRI*x_EMP*x_WLOSS*(x_PEN_K74*Q9+x_PEN_C22*R9) -> 1828067 | AJ9: =x_EMP*x_WAGE*(x_WLOSS*(Q9+R9)+S9)+U9*x_ABS_D*x_WAGE/365 -> 5.077225e+08 | AK9: =AJ9*x_R_FUS -> 1.606434e+08 | AL9: =AJ9*x_R_NFZ -> 39430237 | AM9: =AJ9*x_R_PIT -> 33755511 | AN9: =AJ9*x_R_FP -> 12946924 | AO9: =AA9+AB9+AC9+AD9+AF9 -> 4.6077242e+08 | AP9: =AO9+AE9+AG9+AH9+AI9+AK9+AL9+AM9+AN9 -> 7.4037223e+08 | AQ9: =AO9+AE9+AG9+AJ9 -> 9.6849492e+08 | AR9: =AB9+AC9+AD9+AF9 -> 1.3783343e+08 | AS9: =AR9+AE9+AG9 -> 1.3783343e+08
A10: 2033 | B10: 7 | C10: 4832 | D10: 0 | E10: 0 | F10: 0 | G10: 0 | H10: 2224.233 | I10: 293.219 | J10: 1680.533 | K10: 2883.148 | L10: 1405.327 | M10: 34132.208 | N10: 3510.756 | O10: 94.493 | P10: 93.517 | Q10: 2318.976 | R10: 2128.603 | S10: 4956.95 | T10: 2517.452 | U10: 1656.052 | V10: 122162.84 | W10: 341.368 | X10: 900.889 | Y10: 94.493 | Z10: 1018.015 | AA10: =H10*x_c_F+I10*x_c_CC+J10*x_c_DC+K10*x_c_HCC+L10*x_c_PLT+M10*x_c_SVRn+N10*x_c_SVRcc+O10*x_c_LT+P10*x_c_LT1 -> 3.318566e+08 | AB10: =C10*x_c_DAA -> 109976320 | AC10: =C10*x_c_MON -> 27857108 | AD10: =D10*(1-x_testy) -> 0 | AE10: =E10*(1-x_testy) -> 0 | AF10: =F10*x_NAV -> 0 | AG10: =G10*x_FIX*(1-x_testy) -> 0 | AH10: =x_z_F*U10+(1-x_AGRI)*x_EMP*x_WLOSS*(x_PEN_K74*Q10+x_PEN_C22*R10) -> 31904317 | AI10: =x_AGRI*x_EMP*x_WLOSS*(x_PEN_K74*Q10+x_PEN_C22*R10) -> 1883770.8 | AJ10: =x_EMP*x_WAGE*(x_WLOSS*(Q10+R10)+S10)+U10*x_ABS_D*x_WAGE/365 -> 5.7307241e+08 | AK10: =AJ10*x_R_FUS -> 1.8132011e+08 | AL10: =AJ10*x_R_NFZ -> 44505377 | AM10: =AJ10*x_R_PIT -> 38100246 | AN10: =AJ10*x_R_FP -> 14613347 | AO10: =AA10+AB10+AC10+AD10+AF10 -> 4.6969003e+08 | AP10: =AO10+AE10+AG10+AH10+AI10+AK10+AL10+AM10+AN10 -> 7.820172e+08 | AQ10: =AO10+AE10+AG10+AJ10 -> 1.0427624e+09 | AR10: =AB10+AC10+AD10+AF10 -> 1.3783343e+08 | AS10: =AR10+AE10+AG10 -> 1.3783343e+08
A11: 2034 | B11: 8 | C11: 4832 | D11: 0 | E11: 0 | F11: 0 | G11: 0 | H11: 2213.629 | I11: 302.172 | J11: 1714.258 | K11: 2947.492 | L11: 1393.462 | M11: 37756.249 | N11: 3951.388 | O11: 96.443 | P11: 95.468 | Q11: 2368.312 | R11: 2208.491 | S11: 5693.415 | T11: 2515.801 | U11: 1686.729 | V11: 123496.53 | W11: 348.005 | X11: 914.329 | Y11: 96.443 | Z11: 1038.863 | AA11: =H11*x_c_F+I11*x_c_CC+J11*x_c_DC+K11*x_c_HCC+L11*x_c_PLT+M11*x_c_SVRn+N11*x_c_SVRcc+O11*x_c_LT+P11*x_c_LT1 -> 3.403395e+08 | AB11: =C11*x_c_DAA -> 109976320 | AC11: =C11*x_c_MON -> 27857108 | AD11: =D11*(1-x_testy) -> 0 | AE11: =E11*(1-x_testy) -> 0 | AF11: =F11*x_NAV -> 0 | AG11: =G11*x_FIX*(1-x_testy) -> 0 | AH11: =x_z_F*U11+(1-x_AGRI)*x_EMP*x_WLOSS*(x_PEN_K74*Q11+x_PEN_C22*R11) -> 32810250 | AI11: =x_AGRI*x_EMP*x_WLOSS*(x_PEN_K74*Q11+x_PEN_C22*R11) -> 1939482.4 | AJ11: =x_EMP*x_WAGE*(x_WLOSS*(Q11+R11)+S11)+U11*x_ABS_D*x_WAGE/365 -> 6.4018359e+08 | AK11: =AJ11*x_R_FUS -> 2.0255409e+08 | AL11: =AJ11*x_R_NFZ -> 49717297 | AM11: =AJ11*x_R_PIT -> 42562077 | AN11: =AJ11*x_R_FP -> 16324681 | AO11: =AA11+AB11+AC11+AD11+AF11 -> 4.7817293e+08 | AP11: =AO11+AE11+AG11+AH11+AI11+AK11+AL11+AM11+AN11 -> 8.240808e+08 | AQ11: =AO11+AE11+AG11+AJ11 -> 1.1183565e+09 | AR11: =AB11+AC11+AD11+AF11 -> 1.3783343e+08 | AS11: =AR11+AE11+AG11 -> 1.3783343e+08
A12: 2035 | B12: 9 | C12: 4832 | D12: 0 | E12: 0 | F12: 0 | G12: 0 | H12: 2204.561 | I12: 309.58 | J12: 1746.23 | K12: 3002.435 | L12: 1382.527 | M12: 41297.973 | N12: 4387.381 | O12: 98.276 | P12: 97.359 | Q12: 2418.985 | R12: 2283.662 | S12: 6448.861 | T12: 2514.141 | U12: 1716.052 | V12: 124825.78 | W12: 352.763 | X12: 923.239 | Y12: 98.276 | Z12: 1057.386 | AA12: =H12*x_c_F+I12*x_c_CC+J12*x_c_DC+K12*x_c_HCC+L12*x_c_PLT+M12*x_c_SVRn+N12*x_c_SVRcc+O12*x_c_LT+P12*x_c_LT1 -> 3.4811925e+08 | AB12: =C12*x_c_DAA -> 109976320 | AC12: =C12*x_c_MON -> 27857108 | AD12: =D12*(1-x_testy) -> 0 | AE12: =E12*(1-x_testy) -> 0 | AF12: =F12*x_NAV -> 0 | AG12: =G12*x_FIX*(1-x_testy) -> 0 | AH12: =x_z_F*U12+(1-x_AGRI)*x_EMP*x_WLOSS*(x_PEN_K74*Q12+x_PEN_C22*R12) -> 33689196 | AI12: =x_AGRI*x_EMP*x_WLOSS*(x_PEN_K74*Q12+x_PEN_C22*R12) -> 1993594.3 | AJ12: =x_EMP*x_WAGE*(x_WLOSS*(Q12+R12)+S12)+U12*x_ABS_D*x_WAGE/365 -> 7.0879848e+08 | AK12: =AJ12*x_R_FUS -> 2.2426384e+08 | AL12: =AJ12*x_R_NFZ -> 55045999 | AM12: =AJ12*x_R_PIT -> 47123881 | AN12: =AJ12*x_R_FP -> 18074361 | AO12: =AA12+AB12+AC12+AD12+AF12 -> 4.8595268e+08 | AP12: =AO12+AE12+AG12+AH12+AI12+AK12+AL12+AM12+AN12 -> 8.6614355e+08 | AQ12: =AO12+AE12+AG12+AJ12 -> 1.1947512e+09 | AR12: =AB12+AC12+AD12+AF12 -> 1.3783343e+08 | AS12: =AR12+AE12+AG12 -> 1.3783343e+08
A13: 2036 | B13: 10 | C13: 4832 | D13: 0 | E13: 0 | F13: 0 | G13: 0 | H13: 2197.101 | I13: 315.372 | J13: 1774.721 | K13: 3045.991 | L13: 1372.329 | M13: 44757.851 | N13: 4814.782 | O13: 99.888 | P13: 99.082 | Q13: 2469.528 | R13: 2352.49 | S13: 7220.787 | T13: 2512.473 | U13: 1744.048 | V13: 126144.52 | W13: 355.61 | X13: 927.665 | Y13: 99.888 | Z13: 1072.677 | AA13: =H13*x_c_F+I13*x_c_CC+J13*x_c_DC+K13*x_c_HCC+L13*x_c_PLT+M13*x_c_SVRn+N13*x_c_SVRcc+O13*x_c_LT+P13*x_c_LT1 -> 3.5498212e+08 | AB13: =C13*x_c_DAA -> 109976320 | AC13: =C13*x_c_MON -> 27857108 | AD13: =D13*(1-x_testy) -> 0 | AE13: =E13*(1-x_testy) -> 0 | AF13: =F13*x_NAV -> 0 | AG13: =G13*x_FIX*(1-x_testy) -> 0 | AH13: =x_z_F*U13+(1-x_AGRI)*x_EMP*x_WLOSS*(x_PEN_K74*Q13+x_PEN_C22*R13) -> 34521272 | AI13: =x_AGRI*x_EMP*x_WLOSS*(x_PEN_K74*Q13+x_PEN_C22*R13) -> 2044788.5 | AJ13: =x_EMP*x_WAGE*(x_WLOSS*(Q13+R13)+S13)+U13*x_ABS_D*x_WAGE/365 -> 7.786027e+08 | AK13: =AJ13*x_R_FUS -> 2.4634989e+08 | AL13: =AJ13*x_R_NFZ -> 60467064 | AM13: =AJ13*x_R_PIT -> 51764757 | AN13: =AJ13*x_R_FP -> 19854369 | AO13: =AA13+AB13+AC13+AD13+AF13 -> 4.9281555e+08 | AP13: =AO13+AE13+AG13+AH13+AI13+AK13+AL13+AM13+AN13 -> 9.0781769e+08 | AQ13: =AO13+AE13+AG13+AJ13 -> 1.2714182e+09 | AR13: =AB13+AC13+AD13+AF13 -> 1.3783343e+08 | AS13: =AR13+AE13+AG13 -> 1.3783343e+08
A14: 2037 | B14: 11 | C14: 4832 | D14: 0 | E14: 0 | F14: 0 | G14: 0 | H14: 2191.273 | I14: 319.523 | J14: 1798.289 | K14: 3076.825 | L14: 1362.555 | M14: 48135.673 | N14: 5229.543 | O14: 101.2 | P14: 100.544 | Q14: 2518.59 | R14: 2413.799 | S14: 8005.884 | T14: 2510.796 | U14: 1770.744 | V14: 127445.76 | W14: 356.58 | X14: 927.774 | Y14: 101.2 | Z14: 1084.115 | AA14: =H14*x_c_F+I14*x_c_CC+J14*x_c_DC+K14*x_c_HCC+L14*x_c_PLT+M14*x_c_SVRn+N14*x_c_SVRcc+O14*x_c_LT+P14*x_c_LT1 -> 3.607654e+08 | AB14: =C14*x_c_DAA -> 109976320 | AC14: =C14*x_c_MON -> 27857108 | AD14: =D14*(1-x_testy) -> 0 | AE14: =E14*(1-x_testy) -> 0 | AF14: =F14*x_NAV -> 0 | AG14: =G14*x_FIX*(1-x_testy) -> 0 | AH14: =x_z_F*U14+(1-x_AGRI)*x_EMP*x_WLOSS*(x_PEN_K74*Q14+x_PEN_C22*R14) -> 35290368 | AI14: =x_AGRI*x_EMP*x_WLOSS*(x_PEN_K74*Q14+x_PEN_C22*R14) -> 2091996.5 | AJ14: =x_EMP*x_WAGE*(x_WLOSS*(Q14+R14)+S14)+U14*x_ABS_D*x_WAGE/365 -> 8.4923148e+08 | AK14: =AJ14*x_R_FUS -> 2.6869684e+08 | AL14: =AJ14*x_R_NFZ -> 65952166 | AM14: =AJ14*x_R_PIT -> 56460453 | AN14: =AJ14*x_R_FP -> 21655403 | AO14: =AA14+AB14+AC14+AD14+AF14 -> 4.9859882e+08 | AP14: =AO14+AE14+AG14+AH14+AI14+AK14+AL14+AM14+AN14 -> 9.4874605e+08 | AQ14: =AO14+AE14+AG14+AJ14 -> 1.3478303e+09 | AR14: =AB14+AC14+AD14+AF14 -> 1.3783343e+08 | AS14: =AR14+AE14+AG14 -> 1.3783343e+08
... A52: 2075 | B52: 49 | C52: 4832 | D52: 0 | E52: 0 | F52: 0 | G52: 0 | H52: 2269.693 | I52: 206.878 | J52: 1065.879 | K52: 1833.318 | L52: 667.348 | M52: 144449.32 | N52: 7942.268 | O52: 60.507 | P52: 60.633 | Q52: 627.338 | R52: 925.699 | S52: 2570.878 | T52: 2476.572 | U52: 1830.32 | V52: 179762.59 | W52: 196.568 | X52: 532.393 | Y52: 60.507 | Z52: 642.926 | AA52: =H52*x_c_F+I52*x_c_CC+J52*x_c_DC+K52*x_c_HCC+L52*x_c_PLT+M52*x_c_SVRn+N52*x_c_SVRcc+O52*x_c_LT+P52*x_c_LT1 -> 2.9744688e+08 | AB52: =C52*x_c_DAA -> 109976320 | AC52: =C52*x_c_MON -> 27857108 | AD52: =D52*(1-x_testy) -> 0 | AE52: =E52*(1-x_testy) -> 0 | AF52: =F52*x_NAV -> 0 | AG52: =G52*x_FIX*(1-x_testy) -> 0 | AH52: =x_z_F*U52+(1-x_AGRI)*x_EMP*x_WLOSS*(x_PEN_K74*Q52+x_PEN_C22*R52) -> 13864406 | AI52: =x_AGRI*x_EMP*x_WLOSS*(x_PEN_K74*Q52+x_PEN_C22*R52) -> 667685.76 | AJ52: =x_EMP*x_WAGE*(x_WLOSS*(Q52+R52)+S52)+U52*x_ABS_D*x_WAGE/365 -> 2.7540393e+08 | AK52: =AJ52*x_R_FUS -> 87137803 | AL52: =AJ52*x_R_NFZ -> 21388145 | AM52: =AJ52*x_R_PIT -> 18310003 | AN52: =AJ52*x_R_FP -> 7022800.2 | AO52: =AA52+AB52+AC52+AD52+AF52 -> 4.352803e+08 | AP52: =AO52+AE52+AG52+AH52+AI52+AK52+AL52+AM52+AN52 -> 5.8367115e+08 | AQ52: =AO52+AE52+AG52+AJ52 -> 7.1068423e+08 | AR52: =AB52+AC52+AD52+AF52 -> 1.3783343e+08 | AS52: =AR52+AE52+AG52 -> 1.3783343e+08

Sheet L_S0
A1: S0: Brak leczenia (zaniechanie) – liczebności (silnik, wartości) i koszty (formuły), zł/rok, niezdyskontowane. Szacunek modelu.
A2: rok | B2: t | C2: treated | D2: NFZ_diag | E2: MZ_SW | F2: nNAV | G2: FIXon | H2: cF03 | I2: cF4 | J2: cDC | K2: cHCC | L2: cPLT | M2: cSVn | N2: cSVc | O2: cLTn | P2: cLT1 | Q2: wAdv | R2: wHCC | S2: wGH | T2: cAbs | U2: cAbsW | V2: QALY | W2: newDC | X2: newHCC | Y2: LT | Z2: liverD | AA2: NFZ_med | AB2: NFZ_DAA | AC2: NFZ_mon | AD2: NFZ_diag_k | AE2: MZ_SW_k | AF2: NAV_k | AG2: FIX_k | AH2: ZUS | AI2: KRUS | AJ2: lostw | AK2: lost_FUS | AL2: lost_NFZ | AM2: lost_PIT | AN2: lost_FP | AO2: NFZ | AP2: PUBLIC | AQ2: SOCIETAL | AR2: INV_NFZ | AS2: INV_PUB
A3: 2026 | B3: 0 | C3: 0 | D3: 0 | E3: 0 | F3: 0 | G3: 0 | H3: 5509.246 | I3: 498.943 | J3: 1582.633 | K3: 2532.748 | L3: 1540.438 | M3: 0 | N3: 0 | O3: 89.046 | P3: 44.523 | Q3: 2136.942 | R3: 1708.668 | S3: 312.377 | T3: 6008.189 | U3: 3342.327 | V3: 113001.84 | W3: 272.301 | X3: 727.402 | Y3: 89.046 | Z3: 922.327 | AA3: =H3*x_c_F+I3*x_c_CC+J3*x_c_DC+K3*x_c_HCC+L3*x_c_PLT+M3*x_c_SVRn+N3*x_c_SVRcc+O3*x_c_LT+P3*x_c_LT1 -> 2.8847003e+08 | AB3: =C3*x_c_DAA -> 0 | AC3: =C3*x_c_MON -> 0 | AD3: =D3*(1-x_testy) -> 0 | AE3: =E3*(1-x_testy) -> 0 | AF3: =F3*x_NAV -> 0 | AG3: =G3*x_FIX*(1-x_testy) -> 0 | AH3: =x_z_F*U3+(1-x_AGRI)*x_EMP*x_WLOSS*(x_PEN_K74*Q3+x_PEN_C22*R3) -> 31405570 | AI3: =x_AGRI*x_EMP*x_WLOSS*(x_PEN_K74*Q3+x_PEN_C22*R3) -> 1621654.1 | AJ3: =x_EMP*x_WAGE*(x_WLOSS*(Q3+R3)+S3)+U3*x_ABS_D*x_WAGE/365 -> 1.6232375e+08 | AK3: =AJ3*x_R_FUS -> 51359234 | AL3: =AJ3*x_R_NFZ -> 12606225 | AM3: =AJ3*x_R_PIT -> 10791960 | AN3: =AJ3*x_R_FP -> 4139255.6 | AO3: =AA3+AB3+AC3+AD3+AF3 -> 2.8847003e+08 | AP3: =AO3+AE3+AG3+AH3+AI3+AK3+AL3+AM3+AN3 -> 4.0039393e+08 | AQ3: =AO3+AE3+AG3+AJ3 -> 4.5079378e+08 | AR3: =AB3+AC3+AD3+AF3 -> 0 | AS3: =AR3+AE3+AG3 -> 0
A4: 2027 | B4: 1 | C4: 0 | D4: 0 | E4: 0 | F4: 0 | G4: 0 | H4: 9065.783 | I4: 870.396 | J4: 1577.392 | K4: 2552.872 | L4: 1489.389 | M4: 0 | N4: 0 | O4: 88.331 | P4: 88.689 | Q4: 2147.277 | R4: 1738.504 | S4: 941.663 | T4: 9936.179 | U4: 5676.044 | V4: 113838.04 | W4: 289.562 | X4: 776.664 | Y4: 88.331 | Z4: 930.689 | AA4: =H4*x_c_F+I4*x_c_CC+J4*x_c_DC+K4*x_c_HCC+L4*x_c_PLT+M4*x_c_SVRn+N4*x_c_SVRcc+O4*x_c_LT+P4*x_c_LT1 -> 3.0241239e+08 | AB4: =C4*x_c_DAA -> 0 | AC4: =C4*x_c_MON -> 0 | AD4: =D4*(1-x_testy) -> 0 | AE4: =E4*(1-x_testy) -> 0 | AF4: =F4*x_NAV -> 0 | AG4: =G4*x_FIX*(1-x_testy) -> 0 | AH4: =x_z_F*U4+(1-x_AGRI)*x_EMP*x_WLOSS*(x_PEN_K74*Q4+x_PEN_C22*R4) -> 36469595 | AI4: =x_AGRI*x_EMP*x_WLOSS*(x_PEN_K74*Q4+x_PEN_C22*R4) -> 1639244.2 | AJ4: =x_EMP*x_WAGE*(x_WLOSS*(Q4+R4)+S4)+U4*x_ABS_D*x_WAGE/365 -> 2.2414689e+08 | AK4: =AJ4*x_R_FUS -> 70920076 | AL4: =AJ4*x_R_NFZ -> 17407472 | AM4: =AJ4*x_R_PIT -> 14902221 | AN4: =AJ4*x_R_FP -> 5715745.7 | AO4: =AA4+AB4+AC4+AD4+AF4 -> 3.0241239e+08 | AP4: =AO4+AE4+AG4+AH4+AI4+AK4+AL4+AM4+AN4 -> 4.4946675e+08 | AQ4: =AO4+AE4+AG4+AJ4 -> 5.2655928e+08 | AR4: =AB4+AC4+AD4+AF4 -> 0 | AS4: =AR4+AE4+AG4 -> 0
A5: 2028 | B5: 2 | C5: 0 | D5: 0 | E5: 0 | F5: 0 | G5: 0 | H5: 12524.131 | I5: 1282.177 | J5: 1590.922 | K5: 2617.33 | L5: 1475.935 | M5: 0 | N5: 0 | O5: 88.855 | P5: 88.593 | Q5: 2168.208 | R5: 1802.923 | S5: 1581.493 | T5: 13806.308 | U5: 8090.74 | V5: 114734.08 | W5: 309.818 | X5: 830.282 | Y5: 88.855 | Z5: 941.777 | AA5: =H5*x_c_F+I5*x_c_CC+J5*x_c_DC+K5*x_c_HCC+L5*x_c_PLT+M5*x_c_SVRn+N5*x_c_SVRcc+O5*x_c_LT+P5*x_c_LT1 -> 3.1892487e+08 | AB5: =C5*x_c_DAA -> 0 | AC5: =C5*x_c_MON -> 0 | AD5: =D5*(1-x_testy) -> 0 | AE5: =E5*(1-x_testy) -> 0 | AF5: =F5*x_NAV -> 0 | AG5: =G5*x_FIX*(1-x_testy) -> 0 | AH5: =x_z_F*U5+(1-x_AGRI)*x_EMP*x_WLOSS*(x_PEN_K74*Q5+x_PEN_C22*R5) -> 42000247 | AI5: =x_AGRI*x_EMP*x_WLOSS*(x_PEN_K74*Q5+x_PEN_C22*R5) -> 1676673 | AJ5: =x_EMP*x_WAGE*(x_WLOSS*(Q5+R5)+S5)+U5*x_ABS_D*x_WAGE/365 -> 2.8858566e+08 | AK5: =AJ5*x_R_FUS -> 91308504 | AL5: =AJ5*x_R_NFZ -> 22411851 | AM5: =AJ5*x_R_PIT -> 19186379 | AN5: =AJ5*x_R_FP -> 7358934.4 | AO5: =AA5+AB5+AC5+AD5+AF5 -> 3.1892487e+08 | AP5: =AO5+AE5+AG5+AH5+AI5+AK5+AL5+AM5+AN5 -> 5.0286746e+08 | AQ5: =AO5+AE5+AG5+AJ5 -> 6.0751053e+08 | AR5: =AB5+AC5+AD5+AF5 -> 0 | AS5: =AR5+AE5+AG5 -> 0
A6: 2029 | B6: 3 | C6: 0 | D6: 0 | E6: 0 | F6: 0 | G6: 0 | H6: 15886.581 | I6: 1736.309 | J6: 1622.319 | K6: 2716.741 | L6: 1462.036 | M6: 0 | N6: 0 | O6: 90.506 | P6: 89.681 | Q6: 2204.278 | R6: 1895.414 | S6: 2238.147 | T6: 17622.891 | U6: 10577.531 | V6: 115663.72 | W6: 332.072 | X6: 886.439 | Y6: 90.506 | Z6: 965.574 | AA6: =H6*x_c_F+I6*x_c_CC+J6*x_c_DC+K6*x_c_HCC+L6*x_c_PLT+M6*x_c_SVRn+N6*x_c_SVRcc+O6*x_c_LT+P6*x_c_LT1 -> 3.3833192e+08 | AB6: =C6*x_c_DAA -> 0 | AC6: =C6*x_c_MON -> 0 | AD6: =D6*(1-x_testy) -> 0 | AE6: =E6*(1-x_testy) -> 0 | AF6: =F6*x_NAV -> 0 | AG6: =G6*x_FIX*(1-x_testy) -> 0 | AH6: =x_z_F*U6+(1-x_AGRI)*x_EMP*x_WLOSS*(x_PEN_K74*Q6+x_PEN_C22*R6) -> 47962077 | AI6: =x_AGRI*x_EMP*x_WLOSS*(x_PEN_K74*Q6+x_PEN_C22*R6) -> 1732804.9 | AJ6: =x_EMP*x_WAGE*(x_WLOSS*(Q6+R6)+S6)+U6*x_ABS_D*x_WAGE/365 -> 3.5608499e+08 | AK6: =AJ6*x_R_FUS -> 1.1266529e+08 | AL6: =AJ6*x_R_NFZ -> 27653917 | AM6: =AJ6*x_R_PIT -> 23674016 | AN6: =AJ6*x_R_FP -> 9080167.3 | AO6: =AA6+AB6+AC6+AD6+AF6 -> 3.3833192e+08 | AP6: =AO6+AE6+AG6+AH6+AI6+AK6+AL6+AM6+AN6 -> 5.6110019e+08 | AQ6: =AO6+AE6+AG6+AJ6 -> 6.9441691e+08 | AR6: =AB6+AC6+AD6+AF6 -> 0 | AS6: =AR6+AE6+AG6 -> 0
A7: 2030 | B7: 4 | C7: 0 | D7: 0 | E7: 0 | F7: 0 | G7: 0 | H7: 19156.208 | I7: 2231.599 | J7: 1669.888 | K7: 2842.689 | L7: 1448.65 | M7: 0 | N7: 0 | O7: 93.142 | P7: 91.824 | Q7: 2255.107 | R7: 2010.229 | S7: 2920.285 | T7: 21387.807 | U7: 13127.598 | V7: 116610.46 | W7: 355.49 | X7: 943.617 | Y7: 93.142 | Z7: 999.539 | AA7: =H7*x_c_F+I7*x_c_CC+J7*x_c_DC+K7*x_c_HCC+L7*x_c_PLT+M7*x_c_SVRn+N7*x_c_SVRcc+O7*x_c_LT+P7*x_c_LT1 -> 3.60052e+08 | AB7: =C7*x_c_DAA -> 0 | AC7: =C7*x_c_MON -> 0 | AD7: =D7*(1-x_testy) -> 0 | AE7: =E7*(1-x_testy) -> 0 | AF7: =F7*x_NAV -> 0 | AG7: =G7*x_FIX*(1-x_testy) -> 0 | AH7: =x_z_F*U7+(1-x_AGRI)*x_EMP*x_WLOSS*(x_PEN_K74*Q7+x_PEN_C22*R7) -> 54295378 | AI7: =x_AGRI*x_EMP*x_WLOSS*(x_PEN_K74*Q7+x_PEN_C22*R7) -> 1804891.6 | AJ7: =x_EMP*x_WAGE*(x_WLOSS*(Q7+R7)+S7)+U7*x_ABS_D*x_WAGE/365 -> 4.2715675e+08 | AK7: =AJ7*x_R_FUS -> 1.3515239e+08 | AL7: =AJ7*x_R_NFZ -> 33173420 | AM7: =AJ7*x_R_PIT -> 28399163 | AN7: =AJ7*x_R_FP -> 10892497 | AO7: =AA7+AB7+AC7+AD7+AF7 -> 3.60052e+08 | AP7: =AO7+AE7+AG7+AH7+AI7+AK7+AL7+AM7+AN7 -> 6.2376975e+08 | AQ7: =AO7+AE7+AG7+AJ7 -> 7.8720875e+08 | AR7: =AB7+AC7+AD7+AF7 -> 0 | AS7: =AR7+AE7+AG7 -> 0
A8: 2031 | B8: 5 | C8: 0 | D8: 0 | E8: 0 | F8: 0 | G8: 0 | H8: 22336.98 | I8: 2764.61 | J8: 1731.46 | K8: 2987.771 | L8: 1436.598 | M8: 0 | N8: 0 | O8: 96.607 | P8: 94.875 | Q8: 2319.901 | R8: 2142.36 | S8: 3634.83 | T8: 25101.589 | U8: 15732.575 | V8: 117562.58 | W8: 379.386 | X8: 1000.581 | Y8: 96.607 | Z8: 1041.337 | AA8: =H8*x_c_F+I8*x_c_CC+J8*x_c_DC+K8*x_c_HCC+L8*x_c_PLT+M8*x_c_SVRn+N8*x_c_SVRcc+O8*x_c_LT+P8*x_c_LT1 -> 3.8353921e+08 | AB8: =C8*x_c_DAA -> 0 | AC8: =C8*x_c_MON -> 0 | AD8: =D8*(1-x_testy) -> 0 | AE8: =E8*(1-x_testy) -> 0 | AF8: =F8*x_NAV -> 0 | AG8: =G8*x_FIX*(1-x_testy) -> 0 | AH8: =x_z_F*U8+(1-x_AGRI)*x_EMP*x_WLOSS*(x_PEN_K74*Q8+x_PEN_C22*R8) -> 60943939 | AI8: =x_AGRI*x_EMP*x_WLOSS*(x_PEN_K74*Q8+x_PEN_C22*R8) -> 1890354.5 | AJ8: =x_EMP*x_WAGE*(x_WLOSS*(Q8+R8)+S8)+U8*x_ABS_D*x_WAGE/365 -> 5.021767e+08 | AK8: =AJ8*x_R_FUS -> 1.5888871e+08 | AL8: =AJ8*x_R_NFZ -> 38999545 | AM8: =AJ8*x_R_PIT -> 33386803 | AN8: =AJ8*x_R_FP -> 12805506 | AO8: =AA8+AB8+AC8+AD8+AF8 -> 3.8353921e+08 | AP8: =AO8+AE8+AG8+AH8+AI8+AK8+AL8+AM8+AN8 -> 6.9045406e+08 | AQ8: =AO8+AE8+AG8+AJ8 -> 8.8571591e+08 | AR8: =AB8+AC8+AD8+AF8 -> 0 | AS8: =AR8+AE8+AG8 -> 0
A9: 2032 | B9: 6 | C9: 0 | D9: 0 | E9: 0 | F9: 0 | G9: 0 | H9: 25432.989 | I9: 3330.304 | J9: 1804.567 | K9: 3145.499 | L9: 1426.504 | M9: 0 | N9: 0 | O9: 100.735 | P9: 98.671 | Q9: 2397.549 | R9: 2287.456 | S9: 4387.053 | T9: 28763.293 | U9: 18384.376 | V9: 118509.01 | W9: 403.184 | X9: 1056.289 | Y9: 100.735 | Z9: 1088.803 | AA9: =H9*x_c_F+I9*x_c_CC+J9*x_c_DC+K9*x_c_HCC+L9*x_c_PLT+M9*x_c_SVRn+N9*x_c_SVRcc+O9*x_c_LT+P9*x_c_LT1 -> 4.0828099e+08 | AB9: =C9*x_c_DAA -> 0 | AC9: =C9*x_c_MON -> 0 | AD9: =D9*(1-x_testy) -> 0 | AE9: =E9*(1-x_testy) -> 0 | AF9: =F9*x_NAV -> 0 | AG9: =G9*x_FIX*(1-x_testy) -> 0 | AH9: =x_z_F*U9+(1-x_AGRI)*x_EMP*x_WLOSS*(x_PEN_K74*Q9+x_PEN_C22*R9) -> 67854710 | AI9: =x_AGRI*x_EMP*x_WLOSS*(x_PEN_K74*Q9+x_PEN_C22*R9) -> 1986786 | AJ9: =x_EMP*x_WAGE*(x_WLOSS*(Q9+R9)+S9)+U9*x_ABS_D*x_WAGE/365 -> 5.8139174e+08 | AK9: =AJ9*x_R_FUS -> 1.8395235e+08 | AL9: =AJ9*x_R_NFZ -> 45151464 | AM9: =AJ9*x_R_PIT -> 38653350 | AN9: =AJ9*x_R_FP -> 14825489 | AO9: =AA9+AB9+AC9+AD9+AF9 -> 4.0828099e+08 | AP9: =AO9+AE9+AG9+AH9+AI9+AK9+AL9+AM9+AN9 -> 7.6070513e+08 | AQ9: =AO9+AE9+AG9+AJ9 -> 9.8967273e+08 | AR9: =AB9+AC9+AD9+AF9 -> 0 | AS9: =AR9+AE9+AG9 -> 0
A10: 2033 | B10: 7 | C10: 0 | D10: 0 | E10: 0 | F10: 0 | G10: 0 | H10: 28448.565 | I10: 3922.675 | J10: 1886.63 | K10: 3310.279 | L10: 1418.816 | M10: 0 | N10: 0 | O10: 105.362 | P10: 103.048 | Q10: 2486.734 | R10: 2441.78 | S10: 5180.749 | T10: 32371.24 | U10: 21075.291 | V10: 119440.68 | W10: 426.424 | X10: 1109.922 | Y10: 105.362 | Z10: 1140.041 | AA10: =H10*x_c_F+I10*x_c_CC+J10*x_c_DC+K10*x_c_HCC+L10*x_c_PLT+M10*x_c_SVRn+N10*x_c_SVRcc+O10*x_c_LT+P10*x_c_LT1 -> 4.3380952e+08 | AB10: =C10*x_c_DAA -> 0 | AC10: =C10*x_c_MON -> 0 | AD10: =D10*(1-x_testy) -> 0 | AE10: =E10*(1-x_testy) -> 0 | AF10: =F10*x_NAV -> 0 | AG10: =G10*x_FIX*(1-x_testy) -> 0 | AH10: =x_z_F*U10+(1-x_AGRI)*x_EMP*x_WLOSS*(x_PEN_K74*Q10+x_PEN_C22*R10) -> 74978373 | AI10: =x_AGRI*x_EMP*x_WLOSS*(x_PEN_K74*Q10+x_PEN_C22*R10) -> 2091974.1 | AJ10: =x_EMP*x_WAGE*(x_WLOSS*(Q10+R10)+S10)+U10*x_ABS_D*x_WAGE/365 -> 6.6493735e+08 | AK10: =AJ10*x_R_FUS -> 2.1038618e+08 | AL10: =AJ10*x_R_NFZ -> 51639700 | AM10: =AJ10*x_R_PIT -> 44207811 | AN10: =AJ10*x_R_FP -> 16955903 | AO10: =AA10+AB10+AC10+AD10+AF10 -> 4.3380952e+08 | AP10: =AO10+AE10+AG10+AH10+AI10+AK10+AL10+AM10+AN10 -> 8.3406946e+08 | AQ10: =AO10+AE10+AG10+AJ10 -> 1.0987469e+09 | AR10: =AB10+AC10+AD10+AF10 -> 0 | AS10: =AR10+AE10+AG10 -> 0
A11: 2034 | B11: 8 | C11: 0 | D11: 0 | E11: 0 | F11: 0 | G11: 0 | H11: 31387.97 | I11: 4535.147 | J11: 1975.074 | K11: 3477.337 | L11: 1413.799 | M11: 0 | N11: 0 | O11: 110.329 | P11: 107.846 | Q11: 2586.013 | R11: 2602.146 | S11: 6018.334 | T11: 35923.118 | U11: 23797.9 | V11: 120350.01 | W11: 448.725 | X11: 1160.8 | Y11: 110.329 | Z11: 1193.323 | AA11: =H11*x_c_F+I11*x_c_CC+J11*x_c_DC+K11*x_c_HCC+L11*x_c_PLT+M11*x_c_SVRn+N11*x_c_SVRcc+O11*x_c_LT+P11*x_c_LT1 -> 4.5970142e+08 | AB11: =C11*x_c_DAA -> 0 | AC11: =C11*x_c_MON -> 0 | AD11: =D11*(1-x_testy) -> 0 | AE11: =E11*(1-x_testy) -> 0 | AF11: =F11*x_NAV -> 0 | AG11: =G11*x_FIX*(1-x_testy) -> 0 | AH11: =x_z_F*U11+(1-x_AGRI)*x_EMP*x_WLOSS*(x_PEN_K74*Q11+x_PEN_C22*R11) -> 82269215 | AI11: =x_AGRI*x_EMP*x_WLOSS*(x_PEN_K74*Q11+x_PEN_C22*R11) -> 2203905.3 | AJ11: =x_EMP*x_WAGE*(x_WLOSS*(Q11+R11)+S11)+U11*x_ABS_D*x_WAGE/365 -> 7.5284621e+08 | AK11: =AJ11*x_R_FUS -> 2.3820054e+08 | AL11: =AJ11*x_R_NFZ -> 58466790 | AM11: =AJ11*x_R_PIT -> 50052359 | AN11: =AJ11*x_R_FP -> 19197578 | AO11: =AA11+AB11+AC11+AD11+AF11 -> 4.5970142e+08 | AP11: =AO11+AE11+AG11+AH11+AI11+AK11+AL11+AM11+AN11 -> 9.1009181e+08 | AQ11: =AO11+AE11+AG11+AJ11 -> 1.2125476e+09 | AR11: =AB11+AC11+AD11+AF11 -> 0 | AS11: =AR11+AE11+AG11 -> 0
A12: 2035 | B12: 9 | C12: 0 | D12: 0 | E12: 0 | F12: 0 | G12: 0 | H12: 34255.495 | I12: 5160.983 | J12: 2067.424 | K12: 3642.667 | L12: 1411.557 | M12: 0 | N12: 0 | O12: 115.493 | P12: 112.911 | Q12: 2693.882 | R12: 2765.866 | S12: 6900.983 | T12: 39416.478 | U12: 26545.074 | V12: 121231.05 | W12: 469.801 | X12: 1208.437 | Y12: 115.493 | Z12: 1247.2 | AA12: =H12*x_c_F+I12*x_c_CC+J12*x_c_DC+K12*x_c_HCC+L12*x_c_PLT+M12*x_c_SVRn+N12*x_c_SVRcc+O12*x_c_LT+P12*x_c_LT1 -> 4.8558325e+08 | AB12: =C12*x_c_DAA -> 0 | AC12: =C12*x_c_MON -> 0 | AD12: =D12*(1-x_testy) -> 0 | AE12: =E12*(1-x_testy) -> 0 | AF12: =F12*x_NAV -> 0 | AG12: =G12*x_FIX*(1-x_testy) -> 0 | AH12: =x_z_F*U12+(1-x_AGRI)*x_EMP*x_WLOSS*(x_PEN_K74*Q12+x_PEN_C22*R12) -> 89685156 | AI12: =x_AGRI*x_EMP*x_WLOSS*(x_PEN_K74*Q12+x_PEN_C22*R12) -> 2320767.3 | AJ12: =x_EMP*x_WAGE*(x_WLOSS*(Q12+R12)+S12)+U12*x_ABS_D*x_WAGE/365 -> 8.4506036e+08 | AK12: =AJ12*x_R_FUS -> 2.673771e+08 | AL12: =AJ12*x_R_NFZ -> 65628232 | AM12: =AJ12*x_R_PIT -> 56183140 | AN12: =AJ12*x_R_FP -> 21549039 | AO12: =AA12+AB12+AC12+AD12+AF12 -> 4.8558325e+08 | AP12: =AO12+AE12+AG12+AH12+AI12+AK12+AL12+AM12+AN12 -> 9.8832668e+08 | AQ12: =AO12+AE12+AG12+AJ12 -> 1.3306436e+09 | AR12: =AB12+AC12+AD12+AF12 -> 0 | AS12: =AR12+AE12+AG12 -> 0
A13: 2036 | B13: 10 | C13: 0 | D13: 0 | E13: 0 | F13: 0 | G13: 0 | H13: 37055.021 | I13: 5793.425 | J13: 2161.34 | K13: 3802.909 | L13: 1412.022 | M13: 0 | N13: 0 | O13: 120.712 | P13: 118.103 | Q13: 2808.825 | R13: 2930.691 | S13: 7828.732 | T13: 42848.446 | U13: 29310 | V13: 122078.4 | W13: 489.41 | X13: 1252.407 | Y13: 120.712 | Z13: 1300.336 | AA13: =H13*x_c_F+I13*x_c_CC+J13*x_c_DC+K13*x_c_HCC+L13*x_c_PLT+M13*x_c_SVRn+N13*x_c_SVRcc+O13*x_c_LT+P13*x_c_LT1 -> 5.1111886e+08 | AB13: =C13*x_c_DAA -> 0 | AC13: =C13*x_c_MON -> 0 | AD13: =D13*(1-x_testy) -> 0 | AE13: =E13*(1-x_testy) -> 0 | AF13: =F13*x_NAV -> 0 | AG13: =G13*x_FIX*(1-x_testy) -> 0 | AH13: =x_z_F*U13+(1-x_AGRI)*x_EMP*x_WLOSS*(x_PEN_K74*Q13+x_PEN_C22*R13) -> 97187698 | AI13: =x_AGRI*x_EMP*x_WLOSS*(x_PEN_K74*Q13+x_PEN_C22*R13) -> 2440941 | AJ13: =x_EMP*x_WAGE*(x_WLOSS*(Q13+R13)+S13)+U13*x_ABS_D*x_WAGE/365 -> 9.414396e+08 | AK13: =AJ13*x_R_FUS -> 2.9787149e+08 | AL13: =AJ13*x_R_NFZ -> 73113141 | AM13: =AJ13*x_R_PIT -> 62590834 | AN13: =AJ13*x_R_FP -> 24006710 | AO13: =AA13+AB13+AC13+AD13+AF13 -> 5.1111886e+08 | AP13: =AO13+AE13+AG13+AH13+AI13+AK13+AL13+AM13+AN13 -> 1.0683297e+09 | AQ13: =AO13+AE13+AG13+AJ13 -> 1.4525585e+09 | AR13: =AB13+AC13+AD13+AF13 -> 0 | AS13: =AR13+AE13+AG13 -> 0
A14: 2037 | B14: 11 | C14: 0 | D14: 0 | E14: 0 | F14: 0 | G14: 0 | H14: 39789.75 | I14: 6425.845 | J14: 2254.637 | K14: 3955.249 | L14: 1414.96 | M14: 0 | N14: 0 | O14: 125.864 | P14: 123.288 | Q14: 2929.329 | R14: 3094.738 | S14: 8800.523 | T14: 46215.596 | U14: 32085.95 | V14: 122886.15 | W14: 507.378 | X14: 1292.419 | Y14: 125.864 | Z14: 1351.636 | AA14: =H14*x_c_F+I14*x_c_CC+J14*x_c_DC+K14*x_c_HCC+L14*x_c_PLT+M14*x_c_SVRn+N14*x_c_SVRcc+O14*x_c_LT+P14*x_c_LT1 -> 5.3600979e+08 | AB14: =C14*x_c_DAA -> 0 | AC14: =C14*x_c_MON -> 0 | AD14: =D14*(1-x_testy) -> 0 | AE14: =E14*(1-x_testy) -> 0 | AF14: =F14*x_NAV -> 0 | AG14: =G14*x_FIX*(1-x_testy) -> 0 | AH14: =x_z_F*U14+(1-x_AGRI)*x_EMP*x_WLOSS*(x_PEN_K74*Q14+x_PEN_C22*R14) -> 1.0474104e+08 | AI14: =x_AGRI*x_EMP*x_WLOSS*(x_PEN_K74*Q14+x_PEN_C22*R14) -> 2562974.2 | AJ14: =x_EMP*x_WAGE*(x_WLOSS*(Q14+R14)+S14)+U14*x_ABS_D*x_WAGE/365 -> 1.0417628e+09 | AK14: =AJ14*x_R_FUS -> 3.2961376e+08 | AL14: =AJ14*x_R_NFZ -> 80904343 | AM14: =AJ14*x_R_PIT -> 69260741 | AN14: =AJ14*x_R_FP -> 26564952 | AO14: =AA14+AB14+AC14+AD14+AF14 -> 5.3600979e+08 | AP14: =AO14+AE14+AG14+AH14+AI14+AK14+AL14+AM14+AN14 -> 1.1496576e+09 | AQ14: =AO14+AE14+AG14+AJ14 -> 1.5777726e+09 | AR14: =AB14+AC14+AD14+AF14 -> 0 | AS14: =AR14+AE14+AG14 -> 0
... A52: 2075 | B52: 49 | C52: 0 | D52: 0 | E52: 0 | F52: 0 | G52: 0 | H52: 122772.93 | I52: 26173.44 | J52: 3894.03 | K52: 6428.11 | L52: 1779.538 | M52: 0 | N52: 0 | O52: 215.938 | P52: 214.343 | Q52: 1721.925 | R52: 2600.045 | S52: 6026.219 | T52: 148946.37 | U52: 94187.972 | V52: 150638.68 | W52: 794.766 | X52: 1973.453 | Y52: 215.938 | Z52: 2220.765 | AA52: =H52*x_c_F+I52*x_c_CC+J52*x_c_DC+K52*x_c_HCC+L52*x_c_PLT+M52*x_c_SVRn+N52*x_c_SVRcc+O52*x_c_LT+P52*x_c_LT1 -> 1.1205084e+09 | AB52: =C52*x_c_DAA -> 0 | AC52: =C52*x_c_MON -> 0 | AD52: =D52*(1-x_testy) -> 0 | AE52: =E52*(1-x_testy) -> 0 | AF52: =F52*x_NAV -> 0 | AG52: =G52*x_FIX*(1-x_testy) -> 0 | AH52: =x_z_F*U52+(1-x_AGRI)*x_EMP*x_WLOSS*(x_PEN_K74*Q52+x_PEN_C22*R52) -> 2.2177274e+08 | AI52: =x_AGRI*x_EMP*x_WLOSS*(x_PEN_K74*Q52+x_PEN_C22*R52) -> 1859409.6 | AJ52: =x_EMP*x_WAGE*(x_WLOSS*(Q52+R52)+S52)+U52*x_ABS_D*x_WAGE/365 -> 9.3193037e+08 | AK52: =AJ52*x_R_FUS -> 2.9486277e+08 | AL52: =AJ52*x_R_NFZ -> 72374645 | AM52: =AJ52*x_R_PIT -> 61958621 | AN52: =AJ52*x_R_FP -> 23764225 | AO52: =AA52+AB52+AC52+AD52+AF52 -> 1.1205084e+09 | AP52: =AO52+AE52+AG52+AH52+AI52+AK52+AL52+AM52+AN52 -> 1.7971008e+09 | AQ52: =AO52+AE52+AG52+AJ52 -> 2.0524388e+09 | AR52: =AB52+AC52+AD52+AF52 -> 0 | AS52: =AR52+AE52+AG52 -> 0

Sheet L_I1
A1: I1: Celowane testowanie w szpitalach i laboratoriach (+50 mln zł/rok) – liczebności (silnik, wartości) i koszty (formuły), zł/rok, niezdyskontowane. Szacunek modelu.
A2: rok | B2: t | C2: treated | D2: NFZ_diag | E2: MZ_SW | F2: nNAV | G2: FIXon | H2: cF03 | I2: cF4 | J2: cDC | K2: cHCC | L2: cPLT | M2: cSVn | N2: cSVc | O2: cLTn | P2: cLT1 | Q2: wAdv | R2: wHCC | S2: wGH | T2: cAbs | U2: cAbsW | V2: QALY | W2: newDC | X2: newHCC | Y2: LT | Z2: liverD | AA2: NFZ_med | AB2: NFZ_DAA | AC2: NFZ_mon | AD2: NFZ_diag_k | AE2: MZ_SW_k | AF2: NAV_k | AG2: FIX_k | AH2: ZUS | AI2: KRUS | AJ2: lostw | AK2: lost_FUS | AL2: lost_NFZ | AM2: lost_PIT | AN2: lost_FP | AO2: NFZ | AP2: PUBLIC | AQ2: SOCIETAL | AR2: INV_NFZ | AS2: INV_PUB
A3: 2026 | B3: 0 | C3: 5213.16 | D3: 16666667 | E3: 0 | F3: 0 | G3: 1 | H3: 2581.318 | I3: 231.61 | J3: 1579.158 | K3: 2524.378 | L3: 1540.438 | M3: 7100.45 | N3: 627.462 | O3: 89.046 | P3: 44.523 | Q3: 2134.589 | R3: 1702.999 | S3: 312.377 | T3: 2812.928 | U3: 1558.451 | V3: 113433.47 | W3: 265.352 | X3: 710.662 | Y3: 89.046 | Z3: 922.327 | AA3: =H3*x_c_F+I3*x_c_CC+J3*x_c_DC+K3*x_c_HCC+L3*x_c_PLT+M3*x_c_SVRn+N3*x_c_SVRcc+O3*x_c_LT+P3*x_c_LT1 -> 2.8383355e+08 | AB3: =C3*x_c_DAA -> 1.1865152e+08 | AC3: =C3*x_c_MON -> 30054545 | AD3: =D3*(1-x_testy) -> 16666667 | AE3: =E3*(1-x_testy) -> 0 | AF3: =F3*x_NAV -> 0 | AG3: =G3*x_FIX*(1-x_testy) -> 1223620.5 | AH3: =x_z_F*U3+(1-x_AGRI)*x_EMP*x_WLOSS*(x_PEN_K74*Q3+x_PEN_C22*R3) -> 27685181 | AI3: =x_AGRI*x_EMP*x_WLOSS*(x_PEN_K74*Q3+x_PEN_C22*R3) -> 1618157.1 | AJ3: =x_EMP*x_WAGE*(x_WLOSS*(Q3+R3)+S3)+U3*x_ABS_D*x_WAGE/365 -> 1.5682123e+08 | AK3: =AJ3*x_R_FUS -> 49618236 | AL3: =AJ3*x_R_NFZ -> 12178893 | AM3: =AJ3*x_R_PIT -> 10426130 | AN3: =AJ3*x_R_FP -> 3998941.2 | AO3: =AA3+AB3+AC3+AD3+AF3 -> 4.4920628e+08 | AP3: =AO3+AE3+AG3+AH3+AI3+AK3+AL3+AM3+AN3 -> 5.5595544e+08 | AQ3: =AO3+AE3+AG3+AJ3 -> 6.0725112e+08 | AR3: =AB3+AC3+AD3+AF3 -> 1.6537273e+08 | AS3: =AR3+AE3+AG3 -> 1.6659635e+08
A4: 2027 | B4: 1 | C4: 5576.635 | D4: 33333333 | E4: 0 | F4: 0 | G4: 1 | H4: 2728.1 | I4: 259.776 | J4: 1563.329 | K4: 2519.58 | L4: 1489.389 | M4: 12106.359 | N4: 1093.455 | O4: 87.89 | P4: 88.468 | Q4: 2137.52 | R4: 1715.76 | S4: 939.875 | T4: 2987.876 | U4: 1705.223 | V4: 114593.88 | W4: 274.078 | X4: 738.717 | Y4: 87.89 | Z4: 925.455 | AA4: =H4*x_c_F+I4*x_c_CC+J4*x_c_DC+K4*x_c_HCC+L4*x_c_PLT+M4*x_c_SVRn+N4*x_c_SVRcc+O4*x_c_LT+P4*x_c_LT1 -> 2.8824558e+08 | AB4: =C4*x_c_DAA -> 1.2692421e+08 | AC4: =C4*x_c_MON -> 32150025 | AD4: =D4*(1-x_testy) -> 33333333 | AE4: =E4*(1-x_testy) -> 0 | AF4: =F4*x_NAV -> 0 | AG4: =G4*x_FIX*(1-x_testy) -> 1223620.5 | AH4: =x_z_F*U4+(1-x_AGRI)*x_EMP*x_WLOSS*(x_PEN_K74*Q4+x_PEN_C22*R4) -> 28091794 | AI4: =x_AGRI*x_EMP*x_WLOSS*(x_PEN_K74*Q4+x_PEN_C22*R4) -> 1625088.4 | AJ4: =x_EMP*x_WAGE*(x_WLOSS*(Q4+R4)+S4)+U4*x_ABS_D*x_WAGE/365 -> 2.1126676e+08 | AK4: =AJ4*x_R_FUS -> 66844804 | AL4: =AJ4*x_R_NFZ -> 16407188 | AM4: =AJ4*x_R_PIT -> 14045896 | AN4: =AJ4*x_R_FP -> 5387302.5 | AO4: =AA4+AB4+AC4+AD4+AF4 -> 4.8065315e+08 | AP4: =AO4+AE4+AG4+AH4+AI4+AK4+AL4+AM4+AN4 -> 6.1427884e+08 | AQ4: =AO4+AE4+AG4+AJ4 -> 6.9314353e+08 | AR4: =AB4+AC4+AD4+AF4 -> 1.9240757e+08 | AS4: =AR4+AE4+AG4 -> 1.9363119e+08
A5: 2028 | B5: 2 | C5: 5921.215 | D5: 50000000 | E5: 0 | F5: 0 | G5: 1 | H5: 2782.017 | I5: 281.64 | J5: 1558.707 | K5: 2542.654 | L5: 1475.757 | M5: 17159.078 | N5: 1586.693 | O5: 87.523 | P5: 87.707 | Q5: 2145.234 | R5: 1751.363 | S5: 1572.496 | T5: 3063.657 | U5: 1797.2 | V5: 115841.09 | W5: 283.892 | X5: 766.181 | Y5: 87.523 | Z5: 926.072 | AA5: =H5*x_c_F+I5*x_c_CC+J5*x_c_DC+K5*x_c_HCC+L5*x_c_PLT+M5*x_c_SVRn+N5*x_c_SVRcc+O5*x_c_LT+P5*x_c_LT1 -> 2.9374143e+08 | AB5: =C5*x_c_DAA -> 1.3476685e+08 | AC5: =C5*x_c_MON -> 34136574 | AD5: =D5*(1-x_testy) -> 50000000 | AE5: =E5*(1-x_testy) -> 0 | AF5: =F5*x_NAV -> 0 | AG5: =G5*x_FIX*(1-x_testy) -> 1223620.5 | AH5: =x_z_F*U5+(1-x_AGRI)*x_EMP*x_WLOSS*(x_PEN_K74*Q5+x_PEN_C22*R5) -> 28570668 | AI5: =x_AGRI*x_EMP*x_WLOSS*(x_PEN_K74*Q5+x_PEN_C22*R5) -> 1644242.2 | AJ5: =x_EMP*x_WAGE*(x_WLOSS*(Q5+R5)+S5)+U5*x_ABS_D*x_WAGE/365 -> 2.6689234e+08 | AK5: =AJ5*x_R_FUS -> 84444737 | AL5: =AJ5*x_R_NFZ -> 20727126 | AM5: =AJ5*x_R_PIT -> 17744117 | AN5: =AJ5*x_R_FP -> 6805754.7 | AO5: =AA5+AB5+AC5+AD5+AF5 -> 5.1264486e+08 | AP5: =AO5+AE5+AG5+AH5+AI5+AK5+AL5+AM5+AN5 -> 6.7380513e+08 | AQ5: =AO5+AE5+AG5+AJ5 -> 7.8076082e+08 | AR5: =AB5+AC5+AD5+AF5 -> 2.1890343e+08 | AS5: =AR5+AE5+AG5 -> 2.2012705e+08
A6: 2029 | B6: 3 | C6: 5892.245 | D6: 50000000 | E6: 0 | F6: 0 | G6: 1 | H6: 2750.261 | I6: 295.954 | J6: 1564.041 | K6: 2584.625 | L6: 1461.15 | M6: 22088.431 | N6: 2091.139 | O6: 87.808 | P6: 87.666 | Q6: 2161.57 | R6: 1803.154 | S6: 2212.729 | T6: 3046.215 | U6: 1834.537 | V6: 117143.13 | W6: 294.143 | X6: 792.343 | Y6: 87.808 | Z6: 934.044 | AA6: =H6*x_c_F+I6*x_c_CC+J6*x_c_DC+K6*x_c_HCC+L6*x_c_PLT+M6*x_c_SVRn+N6*x_c_SVRcc+O6*x_c_LT+P6*x_c_LT1 -> 3.0049275e+08 | AB6: =C6*x_c_DAA -> 1.341075e+08 | AC6: =C6*x_c_MON -> 33969558 | AD6: =D6*(1-x_testy) -> 50000000 | AE6: =E6*(1-x_testy) -> 0 | AF6: =F6*x_NAV -> 0 | AG6: =G6*x_FIX*(1-x_testy) -> 1223620.5 | AH6: =x_z_F*U6+(1-x_AGRI)*x_EMP*x_WLOSS*(x_PEN_K74*Q6+x_PEN_C22*R6) -> 29099729 | AI6: =x_AGRI*x_EMP*x_WLOSS*(x_PEN_K74*Q6+x_PEN_C22*R6) -> 1674138.3 | AJ6: =x_EMP*x_WAGE*(x_WLOSS*(Q6+R6)+S6)+U6*x_ABS_D*x_WAGE/365 -> 3.238185e+08 | AK6: =AJ6*x_R_FUS -> 1.0245617e+08 | AL6: =AJ6*x_R_NFZ -> 25148068 | AM6: =AJ6*x_R_PIT -> 21528805 | AN6: =AJ6*x_R_FP -> 8257371.6 | AO6: =AA6+AB6+AC6+AD6+AF6 -> 5.1856981e+08 | AP6: =AO6+AE6+AG6+AH6+AI6+AK6+AL6+AM6+AN6 -> 7.0795771e+08 | AQ6: =AO6+AE6+AG6+AJ6 -> 8.4361192e+08 | AR6: =AB6+AC6+AD6+AF6 -> 2.1807705e+08 | AS6: =AR6+AE6+AG6 -> 2.1930067e+08
A7: 2030 | B7: 4 | C7: 5864.531 | D7: 50000000 | E7: 0 | F7: 0 | G7: 1 | H7: 2719.483 | I7: 309.91 | J7: 1577.536 | K7: 2638.027 | L7: 1446.187 | M7: 26894.042 | N7: 2605.141 | O7: 88.61 | P7: 88.209 | Q7: 2185.593 | R7: 1865.614 | S7: 2865.368 | T7: 3029.393 | U7: 1870.053 | V7: 118486.3 | W7: 303.985 | X7: 815.855 | Y7: 88.61 | Z7: 947.075 | AA7: =H7*x_c_F+I7*x_c_CC+J7*x_c_DC+K7*x_c_HCC+L7*x_c_PLT+M7*x_c_SVRn+N7*x_c_SVRcc+O7*x_c_LT+P7*x_c_LT1 -> 3.0825528e+08 | AB7: =C7*x_c_DAA -> 1.3347673e+08 | AC7: =C7*x_c_MON -> 33809783 | AD7: =D7*(1-x_testy) -> 50000000 | AE7: =E7*(1-x_testy) -> 0 | AF7: =F7*x_NAV -> 0 | AG7: =G7*x_FIX*(1-x_testy) -> 1223620.5 | AH7: =x_z_F*U7+(1-x_AGRI)*x_EMP*x_WLOSS*(x_PEN_K74*Q7+x_PEN_C22*R7) -> 29744215 | AI7: =x_AGRI*x_EMP*x_WLOSS*(x_PEN_K74*Q7+x_PEN_C22*R7) -> 1711911.3 | AJ7: =x_EMP*x_WAGE*(x_WLOSS*(Q7+R7)+S7)+U7*x_ABS_D*x_WAGE/365 -> 3.8239786e+08 | AK7: =AJ7*x_R_FUS -> 1.2099068e+08 | AL7: =AJ7*x_R_NFZ -> 29697400 | AM7: =AJ7*x_R_PIT -> 25423406 | AN7: =AJ7*x_R_FP -> 9751145.4 | AO7: =AA7+AB7+AC7+AD7+AF7 -> 5.2554179e+08 | AP7: =AO7+AE7+AG7+AH7+AI7+AK7+AL7+AM7+AN7 -> 7.4408417e+08 | AQ7: =AO7+AE7+AG7+AJ7 -> 9.0916327e+08 | AR7: =AB7+AC7+AD7+AF7 -> 2.1728651e+08 | AS7: =AR7+AE7+AG7 -> 2.1851013e+08
A8: 2031 | B8: 5 | C8: 5837.956 | D8: 50000000 | E8: 0 | F8: 0 | G8: 1 | H8: 2690.204 | I8: 322.932 | J8: 1596.984 | K8: 2696.394 | L8: 1431.36 | M8: 31576.919 | N8: 3125.977 | O8: 89.777 | P8: 89.193 | Q8: 2215.991 | R8: 1933.958 | S8: 3533.522 | T8: 3013.136 | U8: 1903.771 | V8: 119860.72 | W8: 312.807 | X8: 835.793 | Y8: 89.777 | Z8: 963.061 | AA8: =H8*x_c_F+I8*x_c_CC+J8*x_c_DC+K8*x_c_HCC+L8*x_c_PLT+M8*x_c_SVRn+N8*x_c_SVRcc+O8*x_c_LT+P8*x_c_LT1 -> 3.1653087e+08 | AB8: =C8*x_c_DAA -> 1.3287188e+08 | AC8: =C8*x_c_MON -> 33656575 | AD8: =D8*(1-x_testy) -> 50000000 | AE8: =E8*(1-x_testy) -> 0 | AF8: =F8*x_NAV -> 0 | AG8: =G8*x_FIX*(1-x_testy) -> 1223620.5 | AH8: =x_z_F*U8+(1-x_AGRI)*x_EMP*x_WLOSS*(x_PEN_K74*Q8+x_PEN_C22*R8) -> 30463573 | AI8: =x_AGRI*x_EMP*x_WLOSS*(x_PEN_K74*Q8+x_PEN_C22*R8) -> 1754877.5 | AJ8: =x_EMP*x_WAGE*(x_WLOSS*(Q8+R8)+S8)+U8*x_ABS_D*x_WAGE/365 -> 4.4269601e+08 | AK8: =AJ8*x_R_FUS -> 1.4006902e+08 | AL8: =AJ8*x_R_NFZ -> 34380215 | AM8: =AJ8*x_R_PIT -> 29432279 | AN8: =AJ8*x_R_FP -> 11288748 | AO8: =AA8+AB8+AC8+AD8+AF8 -> 5.3305932e+08 | AP8: =AO8+AE8+AG8+AH8+AI8+AK8+AL8+AM8+AN8 -> 7.8167166e+08 | AQ8: =AO8+AE8+AG8+AJ8 -> 9.7697896e+08 | AR8: =AB8+AC8+AD8+AF8 -> 2.1652845e+08 | AS8: =AR8+AE8+AG8 -> 2.1775207e+08
